#VRML_SIM R2025a utf8

EXTERNPROTO "https://raw.githubusercontent.com/cyberbotics/webots/R2025a/projects/objects/backgrounds/protos/TexturedBackground.proto"
EXTERNPROTO "https://raw.githubusercontent.com/cyberbotics/webots/R2025a/projects/objects/backgrounds/protos/TexturedBackgroundLight.proto"
EXTERNPROTO "https://raw.githubusercontent.com/cyberbotics/webots/R2025a/projects/objects/floors/protos/RectangleArena.proto"

WorldInfo {
}
Viewpoint {
  orientation -0.2205848005757234 0.4798365845544665 0.8491755989652979 0.9923812428009913
  position -2.6835131438082174 -2.3858737081053767 2.3284994894277737
}
TexturedBackground {
}
TexturedBackgroundLight {
}
RectangleArena {
  floorSize 5 5
  wallHeight 0.3
}
Robot {
  translation -0.009306701895543749 -0.020410592567060237 0.09400837755924729
  rotation -0.00013704447964749532 -0.0001027337886785497 0.9999999853322896 -1.8033615159173415
  children [
    DEF BODY_EXTENSION Pose {
    }
    DEF LIDAR Pose {
      translation 0.202 0 -0.004
    }
    Accelerometer {
    }
    InertialUnit {
    }
    Gyro {
    }
    Solid {
      translation 0 0 -0.095
      name "base_footprint"
    }
    DEF BASE_MOBILE_SHAPE Group {
      children [
        DEF BASE Shape {
          appearance PBRAppearance {
            baseColor 0.823529 0.776471 0.776471
            baseColorMap ImageTexture {
              url [
                "https://raw.githubusercontent.com/cyberbotics/webots/R2025a/projects/appearances/protos/textures/matte_car_paint/matte_car_paint_base_color.jpg"
              ]
              filtering 5
            }
            roughnessMap ImageTexture {
              url [
                "https://raw.githubusercontent.com/cyberbotics/webots/R2025a/projects/appearances/protos/textures/glossy_car_paint/glossy_car_paint_roughness.jpg"
              ]
              filtering 5
            }
            metalness 0
            IBLStrength 1.8
            normalMap ImageTexture {
              url [
                "https://raw.githubusercontent.com/cyberbotics/webots/R2025a/projects/appearances/protos/textures/glossy_car_paint/glossy_car_paint_normal.jpg"
              ]
              filtering 5
            }
            normalMapFactor 0.5
            textureTransform TextureTransform {
              scale 4 4
            }
          }
          geometry Mesh {
            url [
              "https://raw.githubusercontent.com/cyberbotics/webots/R2025a/projects/robots/pal_robotics/tiago_base/protos/meshes/base.obj"
            ]
          }
        }
        DEF ANTENNA_LEFT Pose {
          translation -0.201 0.1062 0.195
          children [
            DEF ANTENNA_SHAPE Shape {
              appearance PBRAppearance {
                baseColor 0.133333 0.133333 0.133333
                baseColorMap ImageTexture {
                  url [
                    "https://raw.githubusercontent.com/cyberbotics/webots/R2025a/projects/appearances/protos/textures/matte_car_paint/matte_car_paint_base_color.jpg"
                  ]
                  filtering 5
                }
                roughnessMap ImageTexture {
                  url [
                    "https://raw.githubusercontent.com/cyberbotics/webots/R2025a/projects/appearances/protos/textures/matte_car_paint/matte_car_paint_roughness.jpg"
                  ]
                  filtering 5
                }
                metalness 0
                normalMapFactor 0.5
                textureTransform TextureTransform {
                  scale 10 10
                }
              }
              geometry Mesh {
                url [
                  "https://raw.githubusercontent.com/cyberbotics/webots/R2025a/projects/robots/pal_robotics/tiago_base/protos/meshes/antenna_shape.obj"
                ]
              }
            }
          ]
        }
        DEF ANTENNA_RIGHT Pose {
          translation -0.201 -0.1062 0.195
          children [
            USE ANTENNA_SHAPE
          ]
        }
      ]
    }
    DEF FRONT_SENSOR_1 Pose {
      translation 0.1714 -0.111 0.002
      rotation 0.47980308243485 -0.620398662991083 0.620398662994121 -2.246872814929654
      children [
        Shape {
          appearance PBRAppearance {
            baseColor 0 0 0
          }
          geometry Cylinder {
            height 0.01
            radius 0.01
          }
        }
      ]
      translationStep 0.001
      rotationStep 0.001
    }
    DEF FRONT_SENSOR_2 Pose {
      translation 0.1714 0.111 0.002
      rotation 0.47980308243485 0.620398662991083 0.620398662994121 2.246872814929654
      children [
        Shape {
          appearance PBRAppearance {
            baseColor 0 0 0
          }
          geometry Cylinder {
            height 0.01
            radius 0.01
          }
        }
      ]
      rotationStep 0.001
    }
    DEF BUMPER TouchSensor {
      translation -0.0010883121612808681 3.2792165379084796e-05 0.02939368101180212
      rotation 0.03169395600942279 -0.9344698049601547 -0.3546289282760265 -3.182807371704399e-05
      children [
        DEF BUMPER_SHAPE Shape {
          appearance PBRAppearance {
            baseColor 1 0.552941 0.184314
            transparency 0.01
            roughness 0.1
            metalness 0
          }
          geometry Mesh {
            url [
              "https://raw.githubusercontent.com/cyberbotics/webots/R2025a/projects/robots/pal_robotics/tiago_base/protos/meshes/bumper_shape.obj"
            ]
          }
        }
      ]
      name "base_cover_link"
      boundingObject Pose {
        translation 0 0 0.043
        children [
          Cylinder {
            height 0.086
            radius 0.272
          }
        ]
      }
      physics Physics {
        density -1
        mass 0.25821
      }
      linearVelocity 0.000919750080492934 -0.00023631290887758238 1.7622445740693948e-07
      angularVelocity 1.306609404643551e-06 -8.939869647373898e-07 -0.8885508500595515
    }
    DEF DISTANCE_SENSOR_BACK_LEFT DistanceSensor {
      translation -0.183 0.183 0.173
      rotation 0 0 1 2.3562
      children [
        DEF DS_SHAPE Group {
          children [
            DEF DS_SH_1 Pose {
              translation 0 -0.0115 0
              rotation 0 0 1 -1.5707896938995747
              children [
                Shape {
                  appearance PBRAppearance {
                    baseColor 0 0 0
                    baseColorMap ImageTexture {
                      url [
                        "https://raw.githubusercontent.com/cyberbotics/webots/R2025a/projects/appearances/protos/textures/matte_car_paint/matte_car_paint_base_color.jpg"
                      ]
                      filtering 5
                    }
                    roughnessMap ImageTexture {
                      url [
                        "https://raw.githubusercontent.com/cyberbotics/webots/R2025a/projects/appearances/protos/textures/matte_car_paint/matte_car_paint_roughness.jpg"
                      ]
                      filtering 5
                    }
                    metalness 0
                    normalMapFactor 0.5
                    textureTransform TextureTransform {
                      scale 10 10
                    }
                  }
                }
              ]
            }
            DEF DS_SH_2 Pose {
              translation 0 0.0115 0
              rotation 0 0 1 -1.5707896938995747
              children [
                Shape {
                  appearance PBRAppearance {
                    baseColor 0 0 0
                    baseColorMap ImageTexture {
                      url [
                        "https://raw.githubusercontent.com/cyberbotics/webots/R2025a/projects/appearances/protos/textures/matte_car_paint/matte_car_paint_base_color.jpg"
                      ]
                      filtering 5
                    }
                    roughnessMap ImageTexture {
                      url [
                        "https://raw.githubusercontent.com/cyberbotics/webots/R2025a/projects/appearances/protos/textures/matte_car_paint/matte_car_paint_roughness.jpg"
                      ]
                      filtering 5
                    }
                    metalness 0
                    normalMapFactor 0.5
                    textureTransform TextureTransform {
                      scale 10 10
                    }
                  }
                }
              ]
            }
          ]
        }
      ]
      name "base_sonar_03_link"
    }
    DEF DISTANCE_SENSOR_BACK_MIDDLE DistanceSensor {
      translation -0.259 0 0.173
      rotation 0 0 1 3.1416
      children [
        USE DS_SHAPE
      ]
      name "base_sonar_02_link"
    }
    DEF DISTANCE_SENSOR_BACK_RIGHT DistanceSensor {
      translation -0.183 -0.183 0.173
      rotation 0 0 1 3.927
      children [
        USE DS_SHAPE
      ]
      name "base_sonar_01_link"
    }
    DEF RIGHT_WHEEL_JOINT HingeJoint {
      jointParameters HingeJointParameters {
        position -821.8037019041186
        axis 0 1 0
        anchor 0 -0.2022 0
        suspensionAxis 0 0 1
      }
      device [
        RotationalMotor {
          name "wheel_right_joint"
          acceleration 5.0762
          maxVelocity 10.1523
        }
        PositionSensor {
          name "wheel_right_joint_sensor"
        }
      ]
      endPoint DEF RIGHT_WHEEL Solid {
        translation 0 -0.202 0
        rotation -0.6835080081444465 -0.5161467066915275 0.5161486026077194 4.340732329290166
        children [
          DEF BIG_WHEEL Group {
            children [
              Pose {
                translation 0 0 0.042
                children [
                  Shape {
                    appearance PBRAppearance {
                      baseColor 0 0 0
                      roughness 1
                      metalness 0
                    }
                    geometry Cylinder {
                      height 0.005
                      radius 0.016
                    }
                  }
                ]
              }
              DEF TIRE Shape {
                appearance PBRAppearance {
                  baseColorMap ImageTexture {
                    url [
                      "https://raw.githubusercontent.com/cyberbotics/webots/R2025a/projects/appearances/protos/textures/asphalt/asphalt_base_color.jpg"
                    ]
                    filtering 5
                  }
                  roughnessMap ImageTexture {
                    url [
                      "https://raw.githubusercontent.com/cyberbotics/webots/R2025a/projects/appearances/protos/textures/asphalt/asphalt_roughness.jpg"
                    ]
                    filtering 5
                  }
                  metalness 0
                  IBLStrength 0.5
                  normalMap ImageTexture {
                    url [
                      "https://raw.githubusercontent.com/cyberbotics/webots/R2025a/projects/appearances/protos/textures/asphalt/asphalt_normal.jpg"
                    ]
                    filtering 5
                  }
                  normalMapFactor 1.5
                  occlusionMap ImageTexture {
                    url [
                      "https://raw.githubusercontent.com/cyberbotics/webots/R2025a/projects/appearances/protos/textures/asphalt/asphalt_occlusion.jpg"
                    ]
                    filtering 5
                  }
                  textureTransform TextureTransform {
                    scale 25 25
                  }
                }
                geometry Mesh {
                  url [
                    "https://raw.githubusercontent.com/cyberbotics/webots/R2025a/projects/robots/pal_robotics/tiago_base/protos/meshes/tire.obj"
                  ]
                }
              }
              DEF RIM Shape {
                appearance PBRAppearance {
                  baseColorMap ImageTexture {
                    url [
                      "https://raw.githubusercontent.com/cyberbotics/webots/R2025a/projects/robots/pal_robotics/tiago_base/protos/textures/metal_stainless_clean_base_color.jpg"
                    ]
                  }
                  roughnessMap ImageTexture {
                    url [
                      "https://raw.githubusercontent.com/cyberbotics/webots/R2025a/projects/robots/pal_robotics/tiago_base/protos/textures/metal_stainless_clean_roughness.jpg"
                    ]
                  }
                  metalness 0.9
                  textureTransform TextureTransform {
                    scale 10 10
                  }
                }
                geometry Mesh {
                  url [
                    "https://raw.githubusercontent.com/cyberbotics/webots/R2025a/projects/robots/pal_robotics/tiago_base/protos/meshes/rim.obj"
                  ]
                }
              }
            ]
          }
        ]
        name "wheel_right_link"
        boundingObject Pose {
          children [
            Cylinder {
              height 0.04
              radius 0.0985
            }
          ]
        }
        physics Physics {
          density -1
          mass 1.82362
        }
        linearVelocity 0.03901535596219279 0.1755503937846628 5.8105178050956285e-08
        angularVelocity -1.9532371225945095 0.4306760029614375 -0.8968164991419573
      }
    }
    DEF LEFT_WHEEL_JOINT HingeJoint {
      jointParameters HingeJointParameters {
        position 6613.686253816882
        axis 0 1 0
        anchor 0 0.2022 0
        suspensionAxis 0 0 1
      }
      device [
        RotationalMotor {
          name "wheel_left_joint"
          acceleration 5.0762
          maxVelocity 10.1523
        }
        PositionSensor {
          name "wheel_left_joint_sensor"
        }
      ]
      endPoint DEF LEFT_WHEEL Solid {
        translation 0 0.202 0
        rotation -0.22587355517456342 0.6888314929177051 -0.6888340231416922 3.585882572836201
        children [
          Pose {
            rotation -1 0 0 3.141593
            children [
              DEF BIG_WHEEL Group {
                children [
                  Pose {
                    translation 0 0 0.042
                    children [
                      Shape {
                        appearance PBRAppearance {
                          baseColor 0 0 0
                          roughness 1
                          metalness 0
                        }
                        geometry Cylinder {
                          height 0.005
                          radius 0.016
                        }
                      }
                    ]
                  }
                  DEF TIRE Shape {
                    appearance PBRAppearance {
                      baseColorMap ImageTexture {
                        url [
                          "https://raw.githubusercontent.com/cyberbotics/webots/R2025a/projects/appearances/protos/textures/asphalt/asphalt_base_color.jpg"
                        ]
                        filtering 5
                      }
                      roughnessMap ImageTexture {
                        url [
                          "https://raw.githubusercontent.com/cyberbotics/webots/R2025a/projects/appearances/protos/textures/asphalt/asphalt_roughness.jpg"
                        ]
                        filtering 5
                      }
                      metalness 0
                      IBLStrength 0.5
                      normalMap ImageTexture {
                        url [
                          "https://raw.githubusercontent.com/cyberbotics/webots/R2025a/projects/appearances/protos/textures/asphalt/asphalt_normal.jpg"
                        ]
                        filtering 5
                      }
                      normalMapFactor 1.5
                      occlusionMap ImageTexture {
                        url [
                          "https://raw.githubusercontent.com/cyberbotics/webots/R2025a/projects/appearances/protos/textures/asphalt/asphalt_occlusion.jpg"
                        ]
                        filtering 5
                      }
                      textureTransform TextureTransform {
                        scale 25 25
                      }
                    }
                    geometry Mesh {
                      url [
                        "https://raw.githubusercontent.com/cyberbotics/webots/R2025a/projects/robots/pal_robotics/tiago_base/protos/meshes/tire.obj"
                      ]
                    }
                  }
                  DEF RIM Shape {
                    appearance PBRAppearance {
                      baseColorMap ImageTexture {
                        url [
                          "https://raw.githubusercontent.com/cyberbotics/webots/R2025a/projects/robots/pal_robotics/tiago_base/protos/textures/metal_stainless_clean_base_color.jpg"
                        ]
                      }
                      roughnessMap ImageTexture {
                        url [
                          "https://raw.githubusercontent.com/cyberbotics/webots/R2025a/projects/robots/pal_robotics/tiago_base/protos/textures/metal_stainless_clean_roughness.jpg"
                        ]
                      }
                      metalness 0.9
                      textureTransform TextureTransform {
                        scale 10 10
                      }
                    }
                    geometry Mesh {
                      url [
                        "https://raw.githubusercontent.com/cyberbotics/webots/R2025a/projects/robots/pal_robotics/tiago_base/protos/meshes/rim.obj"
                      ]
                    }
                  }
                ]
              }
            ]
          }
        ]
        name "wheel_left_link"
        boundingObject Pose {
          children [
            Cylinder {
              height 0.04
              radius 0.0985
            }
          ]
        }
        physics Physics {
          density -1
          mass 1.82362
        }
        linearVelocity -0.03901508560298657 -0.17555558231627041 2.8794838182469636e-07
        angularVelocity 1.953240415215544 -0.43067788191538325 -0.8967888110161341
      }
    }
    DEF CASTER_WHEEL_FRONT_RIGHT_JOINT HingeJoint {
      jointParameters HingeJointParameters {
        position 23.126000600996047
        axis 0 0 1
        anchor 0.1695 -0.102 -0.0335
        suspensionSpringConstant 250000
        suspensionAxis 0 0 1
      }
      endPoint DEF CASTER_WHEEL_FRONT_RIGHT Solid {
        translation 0.1695 -0.102 -0.0335
        rotation 0 0 -0.9999999999999999 2.0067406277222988
        children [
          DEF SMALL_WHEEL_JOINT HingeJoint {
            jointParameters HingeJointParameters {
              position 18557.943484862953
              axis 0 1 0
              anchor -0.016 0 -0.04
            }
            endPoint DEF SMALL_WHEEL Solid {
              translation -0.016 0 -0.04
              rotation -0.19769882105730385 -0.6931492070658759 -0.6931517531511405 2.751230227753076
              children [
                DEF SMALL_WHEEL_SHAPE Shape {
                  appearance PBRAppearance {
                    baseColorMap ImageTexture {
                      url [
                        "https://raw.githubusercontent.com/cyberbotics/webots/R2025a/projects/appearances/protos/textures/asphalt/asphalt_base_color.jpg"
                      ]
                      filtering 5
                    }
                    roughnessMap ImageTexture {
                      url [
                        "https://raw.githubusercontent.com/cyberbotics/webots/R2025a/projects/appearances/protos/textures/asphalt/asphalt_roughness.jpg"
                      ]
                      filtering 5
                    }
                    metalness 0
                    IBLStrength 0.5
                    normalMap ImageTexture {
                      url [
                        "https://raw.githubusercontent.com/cyberbotics/webots/R2025a/projects/appearances/protos/textures/asphalt/asphalt_normal.jpg"
                      ]
                      filtering 5
                    }
                    normalMapFactor 1.5
                    occlusionMap ImageTexture {
                      url [
                        "https://raw.githubusercontent.com/cyberbotics/webots/R2025a/projects/appearances/protos/textures/asphalt/asphalt_occlusion.jpg"
                      ]
                      filtering 5
                    }
                    textureTransform TextureTransform {
                      scale 25 25
                    }
                  }
                  geometry Mesh {
                    url [
                      "https://raw.githubusercontent.com/cyberbotics/webots/R2025a/projects/robots/pal_robotics/tiago_base/protos/meshes/small_wheel_shape.obj"
                    ]
                  }
                }
              ]
              name "caster_front_right_2_link"
              boundingObject DEF SMALL_WHEEL_BO Pose {
                children [
                  Cylinder {
                    height 0.015
                    radius 0.025
                  }
                ]
              }
              physics DEF SMALL_WHEEL_PHYSIC Physics {
                density -1
                mass 0.088558
              }
              linearVelocity -0.1360982794293805 0.11039350765873576 -1.3863206289119393e-08
              angularVelocity -4.262350840243238 -5.641941887770439 -0.9094838174081679
            }
          }
          DEF CASTER_SUPPORT Shape {
            appearance PBRAppearance {
              baseColorMap ImageTexture {
                url [
                  "https://raw.githubusercontent.com/cyberbotics/webots/R2025a/projects/appearances/protos/textures/brushed_aluminium/brushed_aluminium_base_color.jpg"
                ]
              }
              roughnessMap ImageTexture {
                url [
                  "https://raw.githubusercontent.com/cyberbotics/webots/R2025a/projects/appearances/protos/textures/brushed_aluminium/brushed_aluminium_roughness.jpg"
                ]
              }
              normalMap ImageTexture {
                url [
                  "https://raw.githubusercontent.com/cyberbotics/webots/R2025a/projects/appearances/protos/textures/brushed_aluminium/brushed_aluminium_normal.jpg"
                ]
              }
              textureTransform TextureTransform {
                rotation -1.57
                scale 2 2
              }
            }
            geometry Mesh {
              url [
                "https://raw.githubusercontent.com/cyberbotics/webots/R2025a/projects/robots/pal_robotics/tiago_base/protos/meshes/caster_support.obj"
              ]
            }
          }
        ]
        name "caster_front_right_1_link"
        boundingObject DEF CASTER_WHEEL_BO Pose {
          translation -0.003 0 -0.022
          children [
            DEF CASTER_SUPPORT_BO Box {
              size 0.036 0.032 0.04
            }
          ]
        }
        physics DEF CASTER_WHEEL_PHYSIC Physics {
          density -1
          mass 0.051448
        }
        linearVelocity -0.1292598087609766 0.11926257664844143 -1.0722884395568774e-07
        angularVelocity -4.6198378116636925e-07 -8.42619330441324e-06 -0.8599808801168892
      }
    }
    DEF CASTER_WHEEL_FRONT_LEFT_JOINT HingeJoint {
      jointParameters HingeJointParameters {
        position 17.925960659834182
        axis 0 0 1
        anchor 0.1695 0.102 -0.0335
        suspensionSpringConstant 250000
        suspensionAxis 0 0 1
      }
      endPoint DEF CASTER_WHEEL_FRONT_LEFT Solid {
        translation 0.1695 0.102 -0.0335
        rotation 0 0 0.9999999999999999 5.3595900454750085
        children [
          DEF SMALL_WHEEL_JOINT HingeJoint {
            jointParameters HingeJointParameters {
              position 19971.191877247413
              axis 0 1 0
              anchor -0.016 0 -0.04
            }
            endPoint DEF SMALL_WHEEL Solid {
              translation -0.016 0 -0.04
              rotation 0.030897889489958794 0.7067678723334274 0.7067704684424401 3.203368552002887
              children [
                DEF SMALL_WHEEL_SHAPE Shape {
                  appearance PBRAppearance {
                    baseColorMap ImageTexture {
                      url [
                        "https://raw.githubusercontent.com/cyberbotics/webots/R2025a/projects/appearances/protos/textures/asphalt/asphalt_base_color.jpg"
                      ]
                      filtering 5
                    }
                    roughnessMap ImageTexture {
                      url [
                        "https://raw.githubusercontent.com/cyberbotics/webots/R2025a/projects/appearances/protos/textures/asphalt/asphalt_roughness.jpg"
                      ]
                      filtering 5
                    }
                    metalness 0
                    IBLStrength 0.5
                    normalMap ImageTexture {
                      url [
                        "https://raw.githubusercontent.com/cyberbotics/webots/R2025a/projects/appearances/protos/textures/asphalt/asphalt_normal.jpg"
                      ]
                      filtering 5
                    }
                    normalMapFactor 1.5
                    occlusionMap ImageTexture {
                      url [
                        "https://raw.githubusercontent.com/cyberbotics/webots/R2025a/projects/appearances/protos/textures/asphalt/asphalt_occlusion.jpg"
                      ]
                      filtering 5
                    }
                    textureTransform TextureTransform {
                      scale 25 25
                    }
                  }
                  geometry Mesh {
                    url [
                      "https://raw.githubusercontent.com/cyberbotics/webots/R2025a/projects/robots/pal_robotics/tiago_base/protos/meshes/small_wheel_shape.obj"
                    ]
                  }
                }
              ]
              name "caster_front_left_2_link"
              boundingObject DEF SMALL_WHEEL_BO Pose {
                children [
                  Cylinder {
                    height 0.015
                    radius 0.025
                  }
                ]
              }
              physics DEF SMALL_WHEEL_PHYSIC Physics {
                density -1
                mass 0.088558
              }
              linearVelocity -0.16086486989030357 -0.06943534965682158 -6.507366045038158e-08
              angularVelocity 2.8928275279988647 -6.186859380083774 -0.9693422446272253
            }
          }
          DEF CASTER_SUPPORT Shape {
            appearance PBRAppearance {
              baseColorMap ImageTexture {
                url [
                  "https://raw.githubusercontent.com/cyberbotics/webots/R2025a/projects/appearances/protos/textures/brushed_aluminium/brushed_aluminium_base_color.jpg"
                ]
              }
              roughnessMap ImageTexture {
                url [
                  "https://raw.githubusercontent.com/cyberbotics/webots/R2025a/projects/appearances/protos/textures/brushed_aluminium/brushed_aluminium_roughness.jpg"
                ]
              }
              normalMap ImageTexture {
                url [
                  "https://raw.githubusercontent.com/cyberbotics/webots/R2025a/projects/appearances/protos/textures/brushed_aluminium/brushed_aluminium_normal.jpg"
                ]
              }
              textureTransform TextureTransform {
                rotation -1.57
                scale 2 2
              }
            }
            geometry Mesh {
              url [
                "https://raw.githubusercontent.com/cyberbotics/webots/R2025a/projects/robots/pal_robotics/tiago_base/protos/meshes/caster_support.obj"
              ]
            }
          }
        ]
        name "caster_front_left_1_link"
        boundingObject DEF CASTER_WHEEL_BO Pose {
          translation -0.003 0 -0.022
          children [
            DEF CASTER_SUPPORT_BO Box {
              size 0.036 0.032 0.04
            }
          ]
        }
        physics DEF CASTER_WHEEL_PHYSIC Physics {
          density -1
          mass 0.051448
        }
        linearVelocity -0.1658303467804165 -0.05853916855134243 -9.215905013446265e-09
        angularVelocity 3.1114185644862918e-06 6.947027962098495e-06 -0.9187157047222606
      }
    }
    DEF CASTER_WHEEL_BACK_RIGHT_JOINT HingeJoint {
      jointParameters HingeJointParameters {
        position -22.92769002262683
        axis 0 0 1
        anchor -0.1735 -0.102 -0.0335
        suspensionSpringConstant 250000
        suspensionAxis 0 0 1
      }
      endPoint DEF CASTER_WHEEL_BACK_RIGHT Solid {
        translation -0.1735 -0.102 -0.0335
        rotation 0 0 1 2.2050512060915155
        children [
          DEF SMALL_WHEEL_JOINT HingeJoint {
            jointParameters HingeJointParameters {
              position 18854.23634514599
              axis 0 1 0
              anchor -0.016 0 -0.04
            }
            endPoint DEF SMALL_WHEEL_JOINT Solid {
              translation -0.016 0 -0.04
              rotation 0.5650481814198668 0.5834029706163276 0.5834051135790169 4.170235633190089
              children [
                DEF SMALL_WHEEL_SHAPE Shape {
                  appearance PBRAppearance {
                    baseColorMap ImageTexture {
                      url [
                        "https://raw.githubusercontent.com/cyberbotics/webots/R2025a/projects/appearances/protos/textures/asphalt/asphalt_base_color.jpg"
                      ]
                      filtering 5
                    }
                    roughnessMap ImageTexture {
                      url [
                        "https://raw.githubusercontent.com/cyberbotics/webots/R2025a/projects/appearances/protos/textures/asphalt/asphalt_roughness.jpg"
                      ]
                      filtering 5
                    }
                    metalness 0
                    IBLStrength 0.5
                    normalMap ImageTexture {
                      url [
                        "https://raw.githubusercontent.com/cyberbotics/webots/R2025a/projects/appearances/protos/textures/asphalt/asphalt_normal.jpg"
                      ]
                      filtering 5
                    }
                    normalMapFactor 1.5
                    occlusionMap ImageTexture {
                      url [
                        "https://raw.githubusercontent.com/cyberbotics/webots/R2025a/projects/appearances/protos/textures/asphalt/asphalt_occlusion.jpg"
                      ]
                      filtering 5
                    }
                    textureTransform TextureTransform {
                      scale 25 25
                    }
                  }
                  geometry Mesh {
                    url [
                      "https://raw.githubusercontent.com/cyberbotics/webots/R2025a/projects/robots/pal_robotics/tiago_base/protos/meshes/small_wheel_shape.obj"
                    ]
                  }
                }
              ]
              name "caster_back_right_2_link"
              boundingObject DEF SMALL_WHEEL_BO Pose {
                children [
                  Cylinder {
                    height 0.015
                    radius 0.025
                  }
                ]
              }
              physics DEF SMALL_WHEEL_PHYSIC Physics {
                density -1
                mass 0.088558
              }
              linearVelocity 0.16453898124409289 0.06874881842392941 4.5353176742307487e-07
              angularVelocity -2.8626752317786117 6.332222499949472 -0.9687090418319961
            }
          }
          DEF CASTER_SUPPORT Shape {
            appearance PBRAppearance {
              baseColorMap ImageTexture {
                url [
                  "https://raw.githubusercontent.com/cyberbotics/webots/R2025a/projects/appearances/protos/textures/brushed_aluminium/brushed_aluminium_base_color.jpg"
                ]
              }
              roughnessMap ImageTexture {
                url [
                  "https://raw.githubusercontent.com/cyberbotics/webots/R2025a/projects/appearances/protos/textures/brushed_aluminium/brushed_aluminium_roughness.jpg"
                ]
              }
              normalMap ImageTexture {
                url [
                  "https://raw.githubusercontent.com/cyberbotics/webots/R2025a/projects/appearances/protos/textures/brushed_aluminium/brushed_aluminium_normal.jpg"
                ]
              }
              textureTransform TextureTransform {
                rotation -1.57
                scale 2 2
              }
            }
            geometry Mesh {
              url [
                "https://raw.githubusercontent.com/cyberbotics/webots/R2025a/projects/robots/pal_robotics/tiago_base/protos/meshes/caster_support.obj"
              ]
            }
          }
        ]
        name "caster_back_right_1_link"
        boundingObject DEF CASTER_WHEEL_BO Pose {
          translation -0.003 0 -0.022
          children [
            DEF CASTER_SUPPORT_BO Box {
              size 0.036 0.032 0.04
            }
          ]
        }
        physics DEF CASTER_WHEEL_PHYSIC Physics {
          density -1
          mass 0.051448
        }
        linearVelocity 0.16936278575029184 0.057774933640371826 3.849835305328182e-07
        angularVelocity 3.3754113988829903e-06 7.391003939810717e-06 -0.9201229262048324
      }
    }
    DEF CASTER_WHEEL_BACK_LEFT_JOINT HingeJoint {
      jointParameters HingeJointParameters {
        position -17.706633499002344
        axis 0 0 1
        anchor -0.1735 0.102 -0.0335
        suspensionSpringConstant 250000
        suspensionAxis 0 0 1
      }
      endPoint DEF CASTER_WHEEL_BACK_LEFT Solid {
        translation -0.1735 0.102 -0.0335
        rotation 0 0 -1 5.140262884643171
        children [
          DEF SMALL_WHEEL_JOINT HingeJoint {
            jointParameters HingeJointParameters {
              position 20131.119701500116
              axis 0 1 0
              anchor -0.016 0 -0.04
            }
            endPoint DEF SMALL_WHEEL Solid {
              translation -0.016 0 -0.04
              rotation -0.9894814966643461 -0.10228951777196962 -0.10228989350304153 1.5813740165392178
              children [
                DEF SMALL_WHEEL_SHAPE Shape {
                  appearance PBRAppearance {
                    baseColorMap ImageTexture {
                      url [
                        "https://raw.githubusercontent.com/cyberbotics/webots/R2025a/projects/appearances/protos/textures/asphalt/asphalt_base_color.jpg"
                      ]
                      filtering 5
                    }
                    roughnessMap ImageTexture {
                      url [
                        "https://raw.githubusercontent.com/cyberbotics/webots/R2025a/projects/appearances/protos/textures/asphalt/asphalt_roughness.jpg"
                      ]
                      filtering 5
                    }
                    metalness 0
                    IBLStrength 0.5
                    normalMap ImageTexture {
                      url [
                        "https://raw.githubusercontent.com/cyberbotics/webots/R2025a/projects/appearances/protos/textures/asphalt/asphalt_normal.jpg"
                      ]
                      filtering 5
                    }
                    normalMapFactor 1.5
                    occlusionMap ImageTexture {
                      url [
                        "https://raw.githubusercontent.com/cyberbotics/webots/R2025a/projects/appearances/protos/textures/asphalt/asphalt_occlusion.jpg"
                      ]
                      filtering 5
                    }
                    textureTransform TextureTransform {
                      scale 25 25
                    }
                  }
                  geometry Mesh {
                    url [
                      "https://raw.githubusercontent.com/cyberbotics/webots/R2025a/projects/robots/pal_robotics/tiago_base/protos/meshes/small_wheel_shape.obj"
                    ]
                  }
                }
              ]
              name "caster_back_left_2_link"
              boundingObject DEF SMALL_WHEEL_BO Pose {
                children [
                  Cylinder {
                    height 0.015
                    radius 0.025
                  }
                ]
              }
              physics DEF SMALL_WHEEL_PHYSIC Physics {
                density -1
                mass 0.088558
              }
              linearVelocity 0.13951753255984828 -0.11111157732426313 3.6951426995211507e-07
              angularVelocity 4.292997084572987 5.780254840061153 -0.9065422157807379
            }
          }
          DEF CASTER_SUPPORT Shape {
            appearance PBRAppearance {
              baseColorMap ImageTexture {
                url [
                  "https://raw.githubusercontent.com/cyberbotics/webots/R2025a/projects/appearances/protos/textures/brushed_aluminium/brushed_aluminium_base_color.jpg"
                ]
              }
              roughnessMap ImageTexture {
                url [
                  "https://raw.githubusercontent.com/cyberbotics/webots/R2025a/projects/appearances/protos/textures/brushed_aluminium/brushed_aluminium_roughness.jpg"
                ]
              }
              normalMap ImageTexture {
                url [
                  "https://raw.githubusercontent.com/cyberbotics/webots/R2025a/projects/appearances/protos/textures/brushed_aluminium/brushed_aluminium_normal.jpg"
                ]
              }
              textureTransform TextureTransform {
                rotation -1.57
                scale 2 2
              }
            }
            geometry Mesh {
              url [
                "https://raw.githubusercontent.com/cyberbotics/webots/R2025a/projects/robots/pal_robotics/tiago_base/protos/meshes/caster_support.obj"
              ]
            }
          }
        ]
        name "caster_back_left_1_link"
        boundingObject DEF CASTER_WHEEL_BO Pose {
          translation -0.003 0 -0.022
          children [
            DEF CASTER_SUPPORT_BO Box {
              size 0.036 0.032 0.04
            }
          ]
        }
        physics DEF CASTER_WHEEL_PHYSIC Physics {
          density -1
          mass 0.051448
        }
        linearVelocity 0.13274433491483068 -0.12003196197037548 4.650537616677566e-07
        angularVelocity -7.136272259912369e-07 -8.289011648138947e-06 -0.8598054806537307
      }
    }
  ]
  name "TIAGo Base"
  model "PAL Robotics - TIAGo Base"
  boundingObject Group {
    children [
      DEF BASE_BO Pose {
        translation 0 0 0.06
        children [
          Shape {
            geometry Cylinder {
              height 0.276
              radius 0.265
            }
          }
        ]
      }
      DEF ANTENNA_LEFT_BO Pose {
        translation -0.201 0.1062 0.28
        children [
          DEF ANTENNA_BO Cylinder {
            height 0.173
            radius 0.007
          }
        ]
      }
      DEF ANTENNA_RIGHT_BO Pose {
        translation -0.201 -0.1062 0.28
        children [
          USE ANTENNA_BO
        ]
      }
    ]
  }
  physics Physics {
    density -1
    mass 28.26649
  }
  controller "tiago_base_controller"
  controllerArgs [
    ""
  ]
  linearVelocity 0.0001384174349652711 -3.3123869925614916e-05 1.7487485428981651e-07
  angularVelocity 1.3066093489847164e-06 -8.939869071621718e-07 -0.888550850120988
}
