#VRML_SIM R2025a utf8

EXTERNPROTO "https://raw.githubusercontent.com/cyberbotics/webots/R2025a/projects/objects/backgrounds/protos/TexturedBackground.proto"
EXTERNPROTO "https://raw.githubusercontent.com/cyberbotics/webots/R2025a/projects/objects/backgrounds/protos/TexturedBackgroundLight.proto"
EXTERNPROTO "https://raw.githubusercontent.com/cyberbotics/webots/R2025a/projects/objects/floors/protos/RectangleArena.proto"

WorldInfo {
}
Viewpoint {
  orientation -0.17891524637058387 0.7282783680363953 0.6615133810184024 0.7111913290699096
  position -2.5456113936495868 -1.3436452740319054 2.3944632269710837
}
TexturedBackground {
}
TexturedBackgroundLight {
}
RectangleArena {
  floorSize 5 5
  wallHeight 0.3
}
Robot {
  translation -0.009306569676071281 -0.020411131465981763 0.09400652786574751
  rotation 0.00013936924438955877 0.00010457190170510194 -0.9999999848204656 1.8043784623913477
  children [
    DEF BODY_EXTENSION Pose {
    }
    DEF LIDAR Pose {
      translation 0.202 0 -0.004
    }
    Accelerometer {
    }
    InertialUnit {
    }
    Gyro {
    }
    Solid {
      translation 0 0 -0.095
      name "base_footprint"
    }
    DEF BASE_MOBILE_SHAPE Group {
      children [
        DEF BASE Shape {
          appearance PBRAppearance {
            baseColor 0.823529 0.776471 0.776471
            baseColorMap ImageTexture {
              url [
                "https://raw.githubusercontent.com/cyberbotics/webots/R2025a/projects/appearances/protos/textures/matte_car_paint/matte_car_paint_base_color.jpg"
              ]
              filtering 5
            }
            roughnessMap ImageTexture {
              url [
                "https://raw.githubusercontent.com/cyberbotics/webots/R2025a/projects/appearances/protos/textures/glossy_car_paint/glossy_car_paint_roughness.jpg"
              ]
              filtering 5
            }
            metalness 0
            IBLStrength 1.8
            normalMap ImageTexture {
              url [
                "https://raw.githubusercontent.com/cyberbotics/webots/R2025a/projects/appearances/protos/textures/glossy_car_paint/glossy_car_paint_normal.jpg"
              ]
              filtering 5
            }
            normalMapFactor 0.5
            textureTransform TextureTransform {
              scale 4 4
            }
          }
          geometry Mesh {
            url [
              "https://raw.githubusercontent.com/cyberbotics/webots/R2025a/projects/robots/pal_robotics/tiago_base/protos/meshes/base.obj"
            ]
          }
        }
        DEF ANTENNA_LEFT Pose {
          translation -0.201 0.1062 0.195
          children [
            DEF ANTENNA_SHAPE Shape {
              appearance PBRAppearance {
                baseColor 0.133333 0.133333 0.133333
                baseColorMap ImageTexture {
                  url [
                    "https://raw.githubusercontent.com/cyberbotics/webots/R2025a/projects/appearances/protos/textures/matte_car_paint/matte_car_paint_base_color.jpg"
                  ]
                  filtering 5
                }
                roughnessMap ImageTexture {
                  url [
                    "https://raw.githubusercontent.com/cyberbotics/webots/R2025a/projects/appearances/protos/textures/matte_car_paint/matte_car_paint_roughness.jpg"
                  ]
                  filtering 5
                }
                metalness 0
                normalMapFactor 0.5
                textureTransform TextureTransform {
                  scale 10 10
                }
              }
              geometry Mesh {
                url [
                  "https://raw.githubusercontent.com/cyberbotics/webots/R2025a/projects/robots/pal_robotics/tiago_base/protos/meshes/antenna_shape.obj"
                ]
              }
            }
          ]
        }
        DEF ANTENNA_RIGHT Pose {
          translation -0.201 -0.1062 0.195
          children [
            USE ANTENNA_SHAPE
          ]
        }
      ]
    }
    DEF FRONT_SENSOR_1 Pose {
      translation 0.1714 -0.111 0.002
      rotation 0.47980308243485 -0.620398662991083 0.620398662994121 -2.246872814929654
      children [
        Shape {
          appearance PBRAppearance {
            baseColor 0 0 0
          }
          geometry Cylinder {
            height 0.01
            radius 0.01
          }
        }
      ]
      translationStep 0.001
      rotationStep 0.001
    }
    DEF FRONT_SENSOR_2 Pose {
      translation 0.1714 0.111 0.002
      rotation 0.47980308243485 0.620398662991083 0.620398662994121 2.246872814929654
      children [
        Shape {
          appearance PBRAppearance {
            baseColor 0 0 0
          }
          geometry Cylinder {
            height 0.01
            radius 0.01
          }
        }
      ]
      rotationStep 0.001
    }
    DEF BUMPER TouchSensor {
      translation -0.0010883110547966444 3.279213968740424e-05 0.029389630725935867
      rotation -0.031693979112164206 0.9344705076231268 0.3546270746440737 3.182804979239291e-05
      children [
        DEF BUMPER_SHAPE Shape {
          appearance PBRAppearance {
            baseColor 1 0.552941 0.184314
            transparency 0.01
            roughness 0.1
            metalness 0
          }
          geometry Mesh {
            url [
              "https://raw.githubusercontent.com/cyberbotics/webots/R2025a/projects/robots/pal_robotics/tiago_base/protos/meshes/bumper_shape.obj"
            ]
          }
        }
      ]
      name "base_cover_link"
      boundingObject Pose {
        translation 0 0 0.043
        children [
          Cylinder {
            height 0.086
            radius 0.272
          }
        ]
      }
      physics Physics {
        density -1
        mass 0.25821
      }
      linearVelocity -4.236709935499918e-08 -1.5169779819520448e-07 5.768519705978161e-07
      angularVelocity -1.3856271485180872e-07 -5.205640033980545e-09 5.689589319051068e-07
    }
    DEF DISTANCE_SENSOR_BACK_LEFT DistanceSensor {
      translation -0.183 0.183 0.173
      rotation 0 0 1 2.3562
      children [
        DEF DS_SHAPE Group {
          children [
            DEF DS_SH_1 Pose {
              translation 0 -0.0115 0
              rotation 0 0 1 -1.5707896938995747
              children [
                Shape {
                  appearance PBRAppearance {
                    baseColor 0 0 0
                    baseColorMap ImageTexture {
                      url [
                        "https://raw.githubusercontent.com/cyberbotics/webots/R2025a/projects/appearances/protos/textures/matte_car_paint/matte_car_paint_base_color.jpg"
                      ]
                      filtering 5
                    }
                    roughnessMap ImageTexture {
                      url [
                        "https://raw.githubusercontent.com/cyberbotics/webots/R2025a/projects/appearances/protos/textures/matte_car_paint/matte_car_paint_roughness.jpg"
                      ]
                      filtering 5
                    }
                    metalness 0
                    normalMapFactor 0.5
                    textureTransform TextureTransform {
                      scale 10 10
                    }
                  }
                }
              ]
            }
            DEF DS_SH_2 Pose {
              translation 0 0.0115 0
              rotation 0 0 1 -1.5707896938995747
              children [
                Shape {
                  appearance PBRAppearance {
                    baseColor 0 0 0
                    baseColorMap ImageTexture {
                      url [
                        "https://raw.githubusercontent.com/cyberbotics/webots/R2025a/projects/appearances/protos/textures/matte_car_paint/matte_car_paint_base_color.jpg"
                      ]
                      filtering 5
                    }
                    roughnessMap ImageTexture {
                      url [
                        "https://raw.githubusercontent.com/cyberbotics/webots/R2025a/projects/appearances/protos/textures/matte_car_paint/matte_car_paint_roughness.jpg"
                      ]
                      filtering 5
                    }
                    metalness 0
                    normalMapFactor 0.5
                    textureTransform TextureTransform {
                      scale 10 10
                    }
                  }
                }
              ]
            }
          ]
        }
      ]
      name "base_sonar_03_link"
    }
    DEF DISTANCE_SENSOR_BACK_MIDDLE DistanceSensor {
      translation -0.259 0 0.173
      rotation 0 0 1 3.1416
      children [
        USE DS_SHAPE
      ]
      name "base_sonar_02_link"
    }
    DEF DISTANCE_SENSOR_BACK_RIGHT DistanceSensor {
      translation -0.183 -0.183 0.173
      rotation 0 0 1 3.927
      children [
        USE DS_SHAPE
      ]
      name "base_sonar_01_link"
    }
    DEF RIGHT_WHEEL_JOINT HingeJoint {
      jointParameters HingeJointParameters {
        position -821.8037017550049
        axis 0 1 0
        anchor 0 -0.2022 0
        suspensionAxis 0 0 1
      }
      device [
        RotationalMotor {
          name "wheel_right_joint"
          acceleration 5.0762
          maxVelocity 10.1523
        }
        PositionSensor {
          name "wheel_right_joint_sensor"
        }
      ]
      endPoint DEF RIGHT_WHEEL Solid {
        translation 0 -0.202 0
        rotation -0.6835079516838258 -0.5161467440754157 0.516148639991745 4.340732252325616
        children [
          DEF BIG_WHEEL Group {
            children [
              Pose {
                translation 0 0 0.042
                children [
                  Shape {
                    appearance PBRAppearance {
                      baseColor 0 0 0
                      roughness 1
                      metalness 0
                    }
                    geometry Cylinder {
                      height 0.005
                      radius 0.016
                    }
                  }
                ]
              }
              DEF TIRE Shape {
                appearance PBRAppearance {
                  baseColorMap ImageTexture {
                    url [
                      "https://raw.githubusercontent.com/cyberbotics/webots/R2025a/projects/appearances/protos/textures/asphalt/asphalt_base_color.jpg"
                    ]
                    filtering 5
                  }
                  roughnessMap ImageTexture {
                    url [
                      "https://raw.githubusercontent.com/cyberbotics/webots/R2025a/projects/appearances/protos/textures/asphalt/asphalt_roughness.jpg"
                    ]
                    filtering 5
                  }
                  metalness 0
                  IBLStrength 0.5
                  normalMap ImageTexture {
                    url [
                      "https://raw.githubusercontent.com/cyberbotics/webots/R2025a/projects/appearances/protos/textures/asphalt/asphalt_normal.jpg"
                    ]
                    filtering 5
                  }
                  normalMapFactor 1.5
                  occlusionMap ImageTexture {
                    url [
                      "https://raw.githubusercontent.com/cyberbotics/webots/R2025a/projects/appearances/protos/textures/asphalt/asphalt_occlusion.jpg"
                    ]
                    filtering 5
                  }
                  textureTransform TextureTransform {
                    scale 25 25
                  }
                }
                geometry Mesh {
                  url [
                    "https://raw.githubusercontent.com/cyberbotics/webots/R2025a/projects/robots/pal_robotics/tiago_base/protos/meshes/tire.obj"
                  ]
                }
              }
              DEF RIM Shape {
                appearance PBRAppearance {
                  baseColorMap ImageTexture {
                    url [
                      "https://raw.githubusercontent.com/cyberbotics/webots/R2025a/projects/robots/pal_robotics/tiago_base/protos/textures/metal_stainless_clean_base_color.jpg"
                    ]
                  }
                  roughnessMap ImageTexture {
                    url [
                      "https://raw.githubusercontent.com/cyberbotics/webots/R2025a/projects/robots/pal_robotics/tiago_base/protos/textures/metal_stainless_clean_roughness.jpg"
                    ]
                  }
                  metalness 0.9
                  textureTransform TextureTransform {
                    scale 10 10
                  }
                }
                geometry Mesh {
                  url [
                    "https://raw.githubusercontent.com/cyberbotics/webots/R2025a/projects/robots/pal_robotics/tiago_base/protos/meshes/rim.obj"
                  ]
                }
              }
            ]
          }
        ]
        name "wheel_right_link"
        boundingObject Pose {
          children [
            Cylinder {
              height 0.04
              radius 0.0985
            }
          ]
        }
        physics Physics {
          density -1
          mass 1.82362
        }
        linearVelocity 3.4723302442554497e-06 -1.0579945245866052e-06 8.747715807639832e-07
        angularVelocity 1.4369917346134948e-06 -7.471111090811671e-07 5.722465871187072e-07
      }
    }
    DEF LEFT_WHEEL_JOINT HingeJoint {
      jointParameters HingeJointParameters {
        position 6613.686253965865
        axis 0 1 0
        anchor 0 0.2022 0
        suspensionAxis 0 0 1
      }
      device [
        RotationalMotor {
          name "wheel_left_joint"
          acceleration 5.0762
          maxVelocity 10.1523
        }
        PositionSensor {
          name "wheel_left_joint_sensor"
        }
      ]
      endPoint DEF LEFT_WHEEL Solid {
        translation 0 0.202 0
        rotation -0.22587360910486937 0.6888314840756393 -0.6888340142995938 3.5858826754606703
        children [
          Pose {
            rotation -1 0 0 3.141593
            children [
              DEF BIG_WHEEL Group {
                children [
                  Pose {
                    translation 0 0 0.042
                    children [
                      Shape {
                        appearance PBRAppearance {
                          baseColor 0 0 0
                          roughness 1
                          metalness 0
                        }
                        geometry Cylinder {
                          height 0.005
                          radius 0.016
                        }
                      }
                    ]
                  }
                  DEF TIRE Shape {
                    appearance PBRAppearance {
                      baseColorMap ImageTexture {
                        url [
                          "https://raw.githubusercontent.com/cyberbotics/webots/R2025a/projects/appearances/protos/textures/asphalt/asphalt_base_color.jpg"
                        ]
                        filtering 5
                      }
                      roughnessMap ImageTexture {
                        url [
                          "https://raw.githubusercontent.com/cyberbotics/webots/R2025a/projects/appearances/protos/textures/asphalt/asphalt_roughness.jpg"
                        ]
                        filtering 5
                      }
                      metalness 0
                      IBLStrength 0.5
                      normalMap ImageTexture {
                        url [
                          "https://raw.githubusercontent.com/cyberbotics/webots/R2025a/projects/appearances/protos/textures/asphalt/asphalt_normal.jpg"
                        ]
                        filtering 5
                      }
                      normalMapFactor 1.5
                      occlusionMap ImageTexture {
                        url [
                          "https://raw.githubusercontent.com/cyberbotics/webots/R2025a/projects/appearances/protos/textures/asphalt/asphalt_occlusion.jpg"
                        ]
                        filtering 5
                      }
                      textureTransform TextureTransform {
                        scale 25 25
                      }
                    }
                    geometry Mesh {
                      url [
                        "https://raw.githubusercontent.com/cyberbotics/webots/R2025a/projects/robots/pal_robotics/tiago_base/protos/meshes/tire.obj"
                      ]
                    }
                  }
                  DEF RIM Shape {
                    appearance PBRAppearance {
                      baseColorMap ImageTexture {
                        url [
                          "https://raw.githubusercontent.com/cyberbotics/webots/R2025a/projects/robots/pal_robotics/tiago_base/protos/textures/metal_stainless_clean_base_color.jpg"
                        ]
                      }
                      roughnessMap ImageTexture {
                        url [
                          "https://raw.githubusercontent.com/cyberbotics/webots/R2025a/projects/robots/pal_robotics/tiago_base/protos/textures/metal_stainless_clean_roughness.jpg"
                        ]
                      }
                      metalness 0.9
                      textureTransform TextureTransform {
                        scale 10 10
                      }
                    }
                    geometry Mesh {
                      url [
                        "https://raw.githubusercontent.com/cyberbotics/webots/R2025a/projects/robots/pal_robotics/tiago_base/protos/meshes/rim.obj"
                      ]
                    }
                  }
                ]
              }
            ]
          }
        ]
        name "wheel_left_link"
        boundingObject Pose {
          children [
            Cylinder {
              height 0.04
              radius 0.0985
            }
          ]
        }
        physics Physics {
          density -1
          mass 1.82362
        }
        linearVelocity -3.5694982638972087e-06 6.629070071781035e-07 8.891943368573352e-07
        angularVelocity 1.587622345603416e-06 -4.91248671586574e-08 5.722609280867432e-07
      }
    }
    DEF CASTER_WHEEL_FRONT_RIGHT_JOINT HingeJoint {
      jointParameters HingeJointParameters {
        position 23.12593673779777
        axis 0 0 1
        anchor 0.1695 -0.102 -0.0335
        suspensionSpringConstant 250000
        suspensionAxis 0 0 1
      }
      endPoint DEF CASTER_WHEEL_FRONT_RIGHT Solid {
        translation 0.1695 -0.102 -0.0335
        rotation 0 0 -0.9999999999999999 2.006804490920577
        children [
          DEF SMALL_WHEEL_JOINT HingeJoint {
            jointParameters HingeJointParameters {
              position 18557.95147276209
              axis 0 1 0
              anchor -0.016 0 -0.04
            }
            endPoint DEF SMALL_WHEEL Solid {
              translation -0.016 0 -0.04
              rotation -0.20057616233380873 -0.6927357640804963 -0.6927383086471057 2.745695068789823
              children [
                DEF SMALL_WHEEL_SHAPE Shape {
                  appearance PBRAppearance {
                    baseColorMap ImageTexture {
                      url [
                        "https://raw.githubusercontent.com/cyberbotics/webots/R2025a/projects/appearances/protos/textures/asphalt/asphalt_base_color.jpg"
                      ]
                      filtering 5
                    }
                    roughnessMap ImageTexture {
                      url [
                        "https://raw.githubusercontent.com/cyberbotics/webots/R2025a/projects/appearances/protos/textures/asphalt/asphalt_roughness.jpg"
                      ]
                      filtering 5
                    }
                    metalness 0
                    IBLStrength 0.5
                    normalMap ImageTexture {
                      url [
                        "https://raw.githubusercontent.com/cyberbotics/webots/R2025a/projects/appearances/protos/textures/asphalt/asphalt_normal.jpg"
                      ]
                      filtering 5
                    }
                    normalMapFactor 1.5
                    occlusionMap ImageTexture {
                      url [
                        "https://raw.githubusercontent.com/cyberbotics/webots/R2025a/projects/appearances/protos/textures/asphalt/asphalt_occlusion.jpg"
                      ]
                      filtering 5
                    }
                    textureTransform TextureTransform {
                      scale 25 25
                    }
                  }
                  geometry Mesh {
                    url [
                      "https://raw.githubusercontent.com/cyberbotics/webots/R2025a/projects/robots/pal_robotics/tiago_base/protos/meshes/small_wheel_shape.obj"
                    ]
                  }
                }
              ]
              name "caster_front_right_2_link"
              boundingObject DEF SMALL_WHEEL_BO Pose {
                children [
                  Cylinder {
                    height 0.015
                    radius 0.025
                  }
                ]
              }
              physics DEF SMALL_WHEEL_PHYSIC Physics {
                density -1
                mass 0.088558
              }
              linearVelocity 2.361642473713758e-07 -2.3289021691267997e-09 1.0313407804474264e-06
              angularVelocity 4.5606526495725255e-06 5.9170569428956174e-06 -2.188925522325137e-05
            }
          }
          DEF CASTER_SUPPORT Shape {
            appearance PBRAppearance {
              baseColorMap ImageTexture {
                url [
                  "https://raw.githubusercontent.com/cyberbotics/webots/R2025a/projects/appearances/protos/textures/brushed_aluminium/brushed_aluminium_base_color.jpg"
                ]
              }
              roughnessMap ImageTexture {
                url [
                  "https://raw.githubusercontent.com/cyberbotics/webots/R2025a/projects/appearances/protos/textures/brushed_aluminium/brushed_aluminium_roughness.jpg"
                ]
              }
              normalMap ImageTexture {
                url [
                  "https://raw.githubusercontent.com/cyberbotics/webots/R2025a/projects/appearances/protos/textures/brushed_aluminium/brushed_aluminium_normal.jpg"
                ]
              }
              textureTransform TextureTransform {
                rotation -1.57
                scale 2 2
              }
            }
            geometry Mesh {
              url [
                "https://raw.githubusercontent.com/cyberbotics/webots/R2025a/projects/robots/pal_robotics/tiago_base/protos/meshes/caster_support.obj"
              ]
            }
          }
        ]
        name "caster_front_right_1_link"
        boundingObject DEF CASTER_WHEEL_BO Pose {
          translation -0.003 0 -0.022
          children [
            DEF CASTER_SUPPORT_BO Box {
              size 0.036 0.032 0.04
            }
          ]
        }
        physics DEF CASTER_WHEEL_PHYSIC Physics {
          density -1
          mass 0.051448
        }
        linearVelocity 2.0586418930368245e-07 -3.791509686210448e-08 6.081360231990311e-07
        angularVelocity -1.2420460596126894e-07 -1.7986709007846864e-08 -2.1885730378663492e-05
      }
    }
    DEF CASTER_WHEEL_FRONT_LEFT_JOINT HingeJoint {
      jointParameters HingeJointParameters {
        position 17.92591227106718
        axis 0 0 1
        anchor 0.1695 0.102 -0.0335
        suspensionSpringConstant 250000
        suspensionAxis 0 0 1
      }
      endPoint DEF CASTER_WHEEL_FRONT_LEFT Solid {
        translation 0.1695 0.102 -0.0335
        rotation 0 0 1 5.359541656708007
        children [
          DEF SMALL_WHEEL_JOINT HingeJoint {
            jointParameters HingeJointParameters {
              position 19971.1998689751
              axis 0 1 0
              anchor -0.016 0 -0.04
            }
            endPoint DEF SMALL_WHEEL Solid {
              translation -0.016 0 -0.04
              rotation 0.03372487103551988 0.7067032489118213 0.706705844783467 3.209016593924771
              children [
                DEF SMALL_WHEEL_SHAPE Shape {
                  appearance PBRAppearance {
                    baseColorMap ImageTexture {
                      url [
                        "https://raw.githubusercontent.com/cyberbotics/webots/R2025a/projects/appearances/protos/textures/asphalt/asphalt_base_color.jpg"
                      ]
                      filtering 5
                    }
                    roughnessMap ImageTexture {
                      url [
                        "https://raw.githubusercontent.com/cyberbotics/webots/R2025a/projects/appearances/protos/textures/asphalt/asphalt_roughness.jpg"
                      ]
                      filtering 5
                    }
                    metalness 0
                    IBLStrength 0.5
                    normalMap ImageTexture {
                      url [
                        "https://raw.githubusercontent.com/cyberbotics/webots/R2025a/projects/appearances/protos/textures/asphalt/asphalt_normal.jpg"
                      ]
                      filtering 5
                    }
                    normalMapFactor 1.5
                    occlusionMap ImageTexture {
                      url [
                        "https://raw.githubusercontent.com/cyberbotics/webots/R2025a/projects/appearances/protos/textures/asphalt/asphalt_occlusion.jpg"
                      ]
                      filtering 5
                    }
                    textureTransform TextureTransform {
                      scale 25 25
                    }
                  }
                  geometry Mesh {
                    url [
                      "https://raw.githubusercontent.com/cyberbotics/webots/R2025a/projects/robots/pal_robotics/tiago_base/protos/meshes/small_wheel_shape.obj"
                    ]
                  }
                }
              ]
              name "caster_front_left_2_link"
              boundingObject DEF SMALL_WHEEL_BO Pose {
                children [
                  Cylinder {
                    height 0.015
                    radius 0.025
                  }
                ]
              }
              physics DEF SMALL_WHEEL_PHYSIC Physics {
                density -1
                mass 0.088558
              }
              linearVelocity -5.0470168846979215e-08 1.2843318600740128e-07 1.0372376686306195e-06
              angularVelocity -1.9333340816229106e-07 1.5626789583989987e-07 -2.2542165966368207e-05
            }
          }
          DEF CASTER_SUPPORT Shape {
            appearance PBRAppearance {
              baseColorMap ImageTexture {
                url [
                  "https://raw.githubusercontent.com/cyberbotics/webots/R2025a/projects/appearances/protos/textures/brushed_aluminium/brushed_aluminium_base_color.jpg"
                ]
              }
              roughnessMap ImageTexture {
                url [
                  "https://raw.githubusercontent.com/cyberbotics/webots/R2025a/projects/appearances/protos/textures/brushed_aluminium/brushed_aluminium_roughness.jpg"
                ]
              }
              normalMap ImageTexture {
                url [
                  "https://raw.githubusercontent.com/cyberbotics/webots/R2025a/projects/appearances/protos/textures/brushed_aluminium/brushed_aluminium_normal.jpg"
                ]
              }
              textureTransform TextureTransform {
                rotation -1.57
                scale 2 2
              }
            }
            geometry Mesh {
              url [
                "https://raw.githubusercontent.com/cyberbotics/webots/R2025a/projects/robots/pal_robotics/tiago_base/protos/meshes/caster_support.obj"
              ]
            }
          }
        ]
        name "caster_front_left_1_link"
        boundingObject DEF CASTER_WHEEL_BO Pose {
          translation -0.003 0 -0.022
          children [
            DEF CASTER_SUPPORT_BO Box {
              size 0.036 0.032 0.04
            }
          ]
        }
        physics DEF CASTER_WHEEL_PHYSIC Physics {
          density -1
          mass 0.051448
        }
        linearVelocity -3.76607559797567e-08 1.0137363761943347e-07 6.165506037261819e-07
        angularVelocity -1.1489781619551741e-07 3.2170472705578678e-09 -2.253675871668902e-05
      }
    }
    DEF CASTER_WHEEL_BACK_RIGHT_JOINT HingeJoint {
      jointParameters HingeJointParameters {
        position -22.927758162188706
        axis 0 0 1
        anchor -0.1735 -0.102 -0.0335
        suspensionSpringConstant 250000
        suspensionAxis 0 0 1
      }
      endPoint DEF CASTER_WHEEL_BACK_RIGHT Solid {
        translation -0.1735 -0.102 -0.0335
        rotation 0 0 1 2.20498306652964
        children [
          DEF SMALL_WHEEL_JOINT HingeJoint {
            jointParameters HingeJointParameters {
              position 18854.24449254245
              axis 0 1 0
              anchor -0.016 0 -0.04
            }
            endPoint DEF SMALL_WHEEL_JOINT Solid {
              translation -0.016 0 -0.04
              rotation 0.5681837166976745 0.581878327790864 0.5818804651532172 4.174982646065545
              children [
                DEF SMALL_WHEEL_SHAPE Shape {
                  appearance PBRAppearance {
                    baseColorMap ImageTexture {
                      url [
                        "https://raw.githubusercontent.com/cyberbotics/webots/R2025a/projects/appearances/protos/textures/asphalt/asphalt_base_color.jpg"
                      ]
                      filtering 5
                    }
                    roughnessMap ImageTexture {
                      url [
                        "https://raw.githubusercontent.com/cyberbotics/webots/R2025a/projects/appearances/protos/textures/asphalt/asphalt_roughness.jpg"
                      ]
                      filtering 5
                    }
                    metalness 0
                    IBLStrength 0.5
                    normalMap ImageTexture {
                      url [
                        "https://raw.githubusercontent.com/cyberbotics/webots/R2025a/projects/appearances/protos/textures/asphalt/asphalt_normal.jpg"
                      ]
                      filtering 5
                    }
                    normalMapFactor 1.5
                    occlusionMap ImageTexture {
                      url [
                        "https://raw.githubusercontent.com/cyberbotics/webots/R2025a/projects/appearances/protos/textures/asphalt/asphalt_occlusion.jpg"
                      ]
                      filtering 5
                    }
                    textureTransform TextureTransform {
                      scale 25 25
                    }
                  }
                  geometry Mesh {
                    url [
                      "https://raw.githubusercontent.com/cyberbotics/webots/R2025a/projects/robots/pal_robotics/tiago_base/protos/meshes/small_wheel_shape.obj"
                    ]
                  }
                }
              ]
              name "caster_back_right_2_link"
              boundingObject DEF SMALL_WHEEL_BO Pose {
                children [
                  Cylinder {
                    height 0.015
                    radius 0.025
                  }
                ]
              }
              physics DEF SMALL_WHEEL_PHYSIC Physics {
                density -1
                mass 0.088558
              }
              linearVelocity -1.7049583714668984e-07 -1.5863698308886695e-07 9.934547476866633e-07
              angularVelocity 3.291031000665713e-06 -8.104163843300496e-06 -3.928175346974291e-05
            }
          }
          DEF CASTER_SUPPORT Shape {
            appearance PBRAppearance {
              baseColorMap ImageTexture {
                url [
                  "https://raw.githubusercontent.com/cyberbotics/webots/R2025a/projects/appearances/protos/textures/brushed_aluminium/brushed_aluminium_base_color.jpg"
                ]
              }
              roughnessMap ImageTexture {
                url [
                  "https://raw.githubusercontent.com/cyberbotics/webots/R2025a/projects/appearances/protos/textures/brushed_aluminium/brushed_aluminium_roughness.jpg"
                ]
              }
              normalMap ImageTexture {
                url [
                  "https://raw.githubusercontent.com/cyberbotics/webots/R2025a/projects/appearances/protos/textures/brushed_aluminium/brushed_aluminium_normal.jpg"
                ]
              }
              textureTransform TextureTransform {
                rotation -1.57
                scale 2 2
              }
            }
            geometry Mesh {
              url [
                "https://raw.githubusercontent.com/cyberbotics/webots/R2025a/projects/robots/pal_robotics/tiago_base/protos/meshes/caster_support.obj"
              ]
            }
          }
        ]
        name "caster_back_right_1_link"
        boundingObject DEF CASTER_WHEEL_BO Pose {
          translation -0.003 0 -0.022
          children [
            DEF CASTER_SUPPORT_BO Box {
              size 0.036 0.032 0.04
            }
          ]
        }
        physics DEF CASTER_WHEEL_PHYSIC Physics {
          density -1
          mass 0.051448
        }
        linearVelocity -8.384531999198888e-08 -3.6083827680165473e-07 5.788696087202679e-07
        angularVelocity -1.5557601625947634e-07 4.105574626287638e-09 -3.927537975265627e-05
      }
    }
    DEF CASTER_WHEEL_BACK_LEFT_JOINT HingeJoint {
      jointParameters HingeJointParameters {
        position -17.706697746541053
        axis 0 0 1
        anchor -0.1735 0.102 -0.0335
        suspensionSpringConstant 250000
        suspensionAxis 0 0 1
      }
      endPoint DEF CASTER_WHEEL_BACK_LEFT Solid {
        translation -0.1735 0.102 -0.0335
        rotation 0 0 -1 5.14032713218188
        children [
          DEF SMALL_WHEEL_JOINT HingeJoint {
            jointParameters HingeJointParameters {
              position 20131.127851689038
              axis 0 1 0
              anchor -0.016 0 -0.04
            }
            endPoint DEF SMALL_WHEEL Solid {
              translation -0.016 0 -0.04
              rotation -0.9902906815199853 -0.0982962235091511 -0.0982965845720073 1.580556606284393
              children [
                DEF SMALL_WHEEL_SHAPE Shape {
                  appearance PBRAppearance {
                    baseColorMap ImageTexture {
                      url [
                        "https://raw.githubusercontent.com/cyberbotics/webots/R2025a/projects/appearances/protos/textures/asphalt/asphalt_base_color.jpg"
                      ]
                      filtering 5
                    }
                    roughnessMap ImageTexture {
                      url [
                        "https://raw.githubusercontent.com/cyberbotics/webots/R2025a/projects/appearances/protos/textures/asphalt/asphalt_roughness.jpg"
                      ]
                      filtering 5
                    }
                    metalness 0
                    IBLStrength 0.5
                    normalMap ImageTexture {
                      url [
                        "https://raw.githubusercontent.com/cyberbotics/webots/R2025a/projects/appearances/protos/textures/asphalt/asphalt_normal.jpg"
                      ]
                      filtering 5
                    }
                    normalMapFactor 1.5
                    occlusionMap ImageTexture {
                      url [
                        "https://raw.githubusercontent.com/cyberbotics/webots/R2025a/projects/appearances/protos/textures/asphalt/asphalt_occlusion.jpg"
                      ]
                      filtering 5
                    }
                    textureTransform TextureTransform {
                      scale 25 25
                    }
                  }
                  geometry Mesh {
                    url [
                      "https://raw.githubusercontent.com/cyberbotics/webots/R2025a/projects/robots/pal_robotics/tiago_base/protos/meshes/small_wheel_shape.obj"
                    ]
                  }
                }
              ]
              name "caster_back_left_2_link"
              boundingObject DEF SMALL_WHEEL_BO Pose {
                children [
                  Cylinder {
                    height 0.015
                    radius 0.025
                  }
                ]
              }
              physics DEF SMALL_WHEEL_PHYSIC Physics {
                density -1
                mass 0.088558
              }
              linearVelocity -7.778556876331758e-08 -3.3544311330035663e-08 9.99352816924627e-07
              angularVelocity -1.0881949361744022e-06 -1.2069843096704192e-06 -4.0204356535094786e-05
            }
          }
          DEF CASTER_SUPPORT Shape {
            appearance PBRAppearance {
              baseColorMap ImageTexture {
                url [
                  "https://raw.githubusercontent.com/cyberbotics/webots/R2025a/projects/appearances/protos/textures/brushed_aluminium/brushed_aluminium_base_color.jpg"
                ]
              }
              roughnessMap ImageTexture {
                url [
                  "https://raw.githubusercontent.com/cyberbotics/webots/R2025a/projects/appearances/protos/textures/brushed_aluminium/brushed_aluminium_roughness.jpg"
                ]
              }
              normalMap ImageTexture {
                url [
                  "https://raw.githubusercontent.com/cyberbotics/webots/R2025a/projects/appearances/protos/textures/brushed_aluminium/brushed_aluminium_normal.jpg"
                ]
              }
              textureTransform TextureTransform {
                rotation -1.57
                scale 2 2
              }
            }
            geometry Mesh {
              url [
                "https://raw.githubusercontent.com/cyberbotics/webots/R2025a/projects/robots/pal_robotics/tiago_base/protos/meshes/caster_support.obj"
              ]
            }
          }
        ]
        name "caster_back_left_1_link"
        boundingObject DEF CASTER_WHEEL_BO Pose {
          translation -0.003 0 -0.022
          children [
            DEF CASTER_SUPPORT_BO Box {
              size 0.036 0.032 0.04
            }
          ]
        }
        physics DEF CASTER_WHEEL_PHYSIC Physics {
          density -1
          mass 0.051448
        }
        linearVelocity -2.2454618084252217e-07 -2.1953746564928152e-07 5.872325652402638e-07
        angularVelocity -1.4618219879782995e-07 2.2083161587852395e-08 -4.019941831425723e-05
      }
    }
  ]
  name "TIAGo Base"
  model "PAL Robotics - TIAGo Base"
  boundingObject Group {
    children [
      DEF BASE_BO Pose {
        translation 0 0 0.06
        children [
          Shape {
            geometry Cylinder {
              height 0.276
              radius 0.265
            }
          }
        ]
      }
      DEF ANTENNA_LEFT_BO Pose {
        translation -0.201 0.1062 0.28
        children [
          DEF ANTENNA_BO Cylinder {
            height 0.173
            radius 0.007
          }
        ]
      }
      DEF ANTENNA_RIGHT_BO Pose {
        translation -0.201 -0.1062 0.28
        children [
          USE ANTENNA_BO
        ]
      }
    ]
  }
  physics Physics {
    density -1
    mass 28.26649
  }
  controller "tiago_base_controller"
  controllerArgs [
    ""
  ]
  linearVelocity -4.179431071621898e-08 -1.535407322218484e-07 5.970988049650721e-07
  angularVelocity -1.3856327091631335e-07 -5.205486666406244e-09 5.68431142336792e-07
}
