#VRML_SIM R2025a utf8

EXTERNPROTO "https://raw.githubusercontent.com/cyberbotics/webots/R2025a/projects/objects/backgrounds/protos/TexturedBackground.proto"
EXTERNPROTO "https://raw.githubusercontent.com/cyberbotics/webots/R2025a/projects/objects/backgrounds/protos/TexturedBackgroundLight.proto"
EXTERNPROTO "https://raw.githubusercontent.com/cyberbotics/webots/R2025a/projects/objects/floors/protos/RectangleArena.proto"

WorldInfo {
}
Viewpoint {
  orientation -0.3025730473785245 -0.3012988067467441 0.9042502861780366 4.607720655713869
  position 0.09652573115901775 2.646929045550985 2.2971317329160055
}
TexturedBackground {
}
TexturedBackgroundLight {
}
RectangleArena {
  translation 0.12 -0.01 0
  wallHeight 0.3
}
Robot {
  translation 0.25376680290929793 0.006458981678863424 0.09397507710263578
  rotation 0.048054196743871076 0.9855588849422623 -0.16237142139756702 0.0027435084296320313
  children [
    DEF BODY_EXTENSION Pose {
    }
    DEF LIDAR Pose {
      translation 0.202 0 -0.004
    }
    Accelerometer {
    }
    InertialUnit {
    }
    Gyro {
    }
    Solid {
      translation 0 0 -0.095
      name "base_footprint"
    }
    DEF BASE_MOBILE_SHAPE Group {
      children [
        DEF BASE Shape {
          appearance PBRAppearance {
            baseColor 0.823529 0.776471 0.776471
            baseColorMap ImageTexture {
              url [
                "https://raw.githubusercontent.com/cyberbotics/webots/R2025a/projects/appearances/protos/textures/matte_car_paint/matte_car_paint_base_color.jpg"
              ]
              filtering 5
            }
            roughnessMap ImageTexture {
              url [
                "https://raw.githubusercontent.com/cyberbotics/webots/R2025a/projects/appearances/protos/textures/glossy_car_paint/glossy_car_paint_roughness.jpg"
              ]
              filtering 5
            }
            metalness 0
            IBLStrength 1.8
            normalMap ImageTexture {
              url [
                "https://raw.githubusercontent.com/cyberbotics/webots/R2025a/projects/appearances/protos/textures/glossy_car_paint/glossy_car_paint_normal.jpg"
              ]
              filtering 5
            }
            normalMapFactor 0.5
            textureTransform TextureTransform {
              scale 4 4
            }
          }
          geometry Mesh {
            url [
              "https://raw.githubusercontent.com/cyberbotics/webots/R2025a/projects/robots/pal_robotics/tiago_base/protos/meshes/base.obj"
            ]
          }
        }
        DEF ANTENNA_LEFT Pose {
          translation -0.201 0.1062 0.195
          children [
            DEF ANTENNA_SHAPE Shape {
              appearance PBRAppearance {
                baseColor 0.133333 0.133333 0.133333
                baseColorMap ImageTexture {
                  url [
                    "https://raw.githubusercontent.com/cyberbotics/webots/R2025a/projects/appearances/protos/textures/matte_car_paint/matte_car_paint_base_color.jpg"
                  ]
                  filtering 5
                }
                roughnessMap ImageTexture {
                  url [
                    "https://raw.githubusercontent.com/cyberbotics/webots/R2025a/projects/appearances/protos/textures/matte_car_paint/matte_car_paint_roughness.jpg"
                  ]
                  filtering 5
                }
                metalness 0
                normalMapFactor 0.5
                textureTransform TextureTransform {
                  scale 10 10
                }
              }
              geometry Mesh {
                url [
                  "https://raw.githubusercontent.com/cyberbotics/webots/R2025a/projects/robots/pal_robotics/tiago_base/protos/meshes/antenna_shape.obj"
                ]
              }
            }
          ]
        }
        DEF ANTENNA_RIGHT Pose {
          translation -0.201 -0.1062 0.195
          children [
            USE ANTENNA_SHAPE
          ]
        }
      ]
    }
    DEF FRONT_SENSOR_1 Pose {
      translation 0.1714 -0.111 0.002
      rotation 0.47980308243485 -0.620398662991083 0.620398662994121 -2.246872814929654
      children [
        Shape {
          appearance PBRAppearance {
            baseColor 0 0 0
          }
          geometry Cylinder {
            height 0.01
            radius 0.01
          }
        }
      ]
      translationStep 0.001
      rotationStep 0.001
    }
    DEF FRONT_SENSOR_2 Pose {
      translation 0.1714 0.111 0.002
      rotation 0.47980308243485 0.620398662991083 0.620398662994121 2.246872814929654
      children [
        Shape {
          appearance PBRAppearance {
            baseColor 0 0 0
          }
          geometry Cylinder {
            height 0.01
            radius 0.01
          }
        }
      ]
      rotationStep 0.001
    }
    DEF BUMPER TouchSensor {
      translation -0.0006196335157090394 2.416405999661024e-05 0.02947095832088109
      rotation -0.026941688044474308 0.9458499578546147 0.32348416139238956 3.619514859047983e-05
      children [
        DEF BUMPER_SHAPE Shape {
          appearance PBRAppearance {
            baseColor 1 0.552941 0.184314
            transparency 0.01
            roughness 0.1
            metalness 0
          }
          geometry Mesh {
            url [
              "https://raw.githubusercontent.com/cyberbotics/webots/R2025a/projects/robots/pal_robotics/tiago_base/protos/meshes/bumper_shape.obj"
            ]
          }
        }
      ]
      name "base_cover_link"
      boundingObject Pose {
        translation 0 0 0.043
        children [
          Cylinder {
            height 0.086
            radius 0.272
          }
        ]
      }
      physics Physics {
        density -1
        mass 0.25821
      }
      linearVelocity 0.09853384401728736 -0.00017979896533899643 -2.714132815593263e-06
      angularVelocity -0.0006516326724387437 0.00011175793359967498 -0.00010021433635573475
    }
    DEF DISTANCE_SENSOR_BACK_LEFT DistanceSensor {
      translation -0.183 0.183 0.173
      rotation 0 0 1 2.3562
      children [
        DEF DS_SHAPE Group {
          children [
            DEF DS_SH_1 Pose {
              translation 0 -0.0115 0
              rotation 0 0 1 -1.5707896938995747
              children [
                Shape {
                  appearance PBRAppearance {
                    baseColor 0 0 0
                    baseColorMap ImageTexture {
                      url [
                        "https://raw.githubusercontent.com/cyberbotics/webots/R2025a/projects/appearances/protos/textures/matte_car_paint/matte_car_paint_base_color.jpg"
                      ]
                      filtering 5
                    }
                    roughnessMap ImageTexture {
                      url [
                        "https://raw.githubusercontent.com/cyberbotics/webots/R2025a/projects/appearances/protos/textures/matte_car_paint/matte_car_paint_roughness.jpg"
                      ]
                      filtering 5
                    }
                    metalness 0
                    normalMapFactor 0.5
                    textureTransform TextureTransform {
                      scale 10 10
                    }
                  }
                }
              ]
            }
            DEF DS_SH_2 Pose {
              translation 0 0.0115 0
              rotation 0 0 1 -1.5707896938995747
              children [
                Shape {
                  appearance PBRAppearance {
                    baseColor 0 0 0
                    baseColorMap ImageTexture {
                      url [
                        "https://raw.githubusercontent.com/cyberbotics/webots/R2025a/projects/appearances/protos/textures/matte_car_paint/matte_car_paint_base_color.jpg"
                      ]
                      filtering 5
                    }
                    roughnessMap ImageTexture {
                      url [
                        "https://raw.githubusercontent.com/cyberbotics/webots/R2025a/projects/appearances/protos/textures/matte_car_paint/matte_car_paint_roughness.jpg"
                      ]
                      filtering 5
                    }
                    metalness 0
                    normalMapFactor 0.5
                    textureTransform TextureTransform {
                      scale 10 10
                    }
                  }
                }
              ]
            }
          ]
        }
      ]
      name "base_sonar_03_link"
    }
    DEF DISTANCE_SENSOR_BACK_MIDDLE DistanceSensor {
      translation -0.259 0 0.173
      rotation 0 0 1 3.1416
      children [
        USE DS_SHAPE
      ]
      name "base_sonar_02_link"
    }
    DEF DISTANCE_SENSOR_BACK_RIGHT DistanceSensor {
      translation -0.183 -0.183 0.173
      rotation 0 0 1 3.927
      children [
        USE DS_SHAPE
      ]
      name "base_sonar_01_link"
    }
    DEF RIGHT_WHEEL_JOINT HingeJoint {
      jointParameters HingeJointParameters {
        position 2015.910800396224
        axis 0 1 0
        anchor 0 -0.2022 0
        suspensionAxis 0 0 1
      }
      device [
        RotationalMotor {
          name "wheel_right_joint"
          acceleration 5.0762
          maxVelocity 10.1523
        }
        PositionSensor {
          name "wheel_right_joint_sensor"
        }
      ]
      endPoint DEF RIGHT_WHEEL Solid {
        translation 0 -0.202 0
        rotation -0.7942572614428591 0.4296242815890318 -0.4296258596900306 4.48404797551707
        children [
          DEF BIG_WHEEL Group {
            children [
              Pose {
                translation 0 0 0.042
                children [
                  Shape {
                    appearance PBRAppearance {
                      baseColor 0 0 0
                      roughness 1
                      metalness 0
                    }
                    geometry Cylinder {
                      height 0.005
                      radius 0.016
                    }
                  }
                ]
              }
              DEF TIRE Shape {
                appearance PBRAppearance {
                  baseColorMap ImageTexture {
                    url [
                      "https://raw.githubusercontent.com/cyberbotics/webots/R2025a/projects/appearances/protos/textures/asphalt/asphalt_base_color.jpg"
                    ]
                    filtering 5
                  }
                  roughnessMap ImageTexture {
                    url [
                      "https://raw.githubusercontent.com/cyberbotics/webots/R2025a/projects/appearances/protos/textures/asphalt/asphalt_roughness.jpg"
                    ]
                    filtering 5
                  }
                  metalness 0
                  IBLStrength 0.5
                  normalMap ImageTexture {
                    url [
                      "https://raw.githubusercontent.com/cyberbotics/webots/R2025a/projects/appearances/protos/textures/asphalt/asphalt_normal.jpg"
                    ]
                    filtering 5
                  }
                  normalMapFactor 1.5
                  occlusionMap ImageTexture {
                    url [
                      "https://raw.githubusercontent.com/cyberbotics/webots/R2025a/projects/appearances/protos/textures/asphalt/asphalt_occlusion.jpg"
                    ]
                    filtering 5
                  }
                  textureTransform TextureTransform {
                    scale 25 25
                  }
                }
                geometry Mesh {
                  url [
                    "https://raw.githubusercontent.com/cyberbotics/webots/R2025a/projects/robots/pal_robotics/tiago_base/protos/meshes/tire.obj"
                  ]
                }
              }
              DEF RIM Shape {
                appearance PBRAppearance {
                  baseColorMap ImageTexture {
                    url [
                      "https://raw.githubusercontent.com/cyberbotics/webots/R2025a/projects/robots/pal_robotics/tiago_base/protos/textures/metal_stainless_clean_base_color.jpg"
                    ]
                  }
                  roughnessMap ImageTexture {
                    url [
                      "https://raw.githubusercontent.com/cyberbotics/webots/R2025a/projects/robots/pal_robotics/tiago_base/protos/textures/metal_stainless_clean_roughness.jpg"
                    ]
                  }
                  metalness 0.9
                  textureTransform TextureTransform {
                    scale 10 10
                  }
                }
                geometry Mesh {
                  url [
                    "https://raw.githubusercontent.com/cyberbotics/webots/R2025a/projects/robots/pal_robotics/tiago_base/protos/meshes/rim.obj"
                  ]
                }
              }
            ]
          }
        ]
        name "wheel_right_link"
        boundingObject Pose {
          children [
            Cylinder {
              height 0.04
              radius 0.0985
            }
          ]
        }
        physics Physics {
          density -1
          mass 1.82362
        }
        linearVelocity 0.09848722925608504 -0.00022371043562011893 0.0001263603579970502
        angularVelocity -0.00021098766680959305 1.0001070791236712 3.9681045417741374e-05
      }
    }
    DEF LEFT_WHEEL_JOINT HingeJoint {
      jointParameters HingeJointParameters {
        position 2050.5098270615044
        axis 0 1 0
        anchor 0 0.2022 0
        suspensionAxis 0 0 1
      }
      device [
        RotationalMotor {
          name "wheel_left_joint"
          acceleration 5.0762
          maxVelocity 10.1523
        }
        PositionSensor {
          name "wheel_left_joint_sensor"
        }
      ]
      endPoint DEF LEFT_WHEEL Solid {
        translation 0 0.202 0
        rotation 0.3418162438905633 0.6645142629690752 -0.6645167038707257 2.4828636082535205
        children [
          Pose {
            rotation -1 0 0 3.141593
            children [
              DEF BIG_WHEEL Group {
                children [
                  Pose {
                    translation 0 0 0.042
                    children [
                      Shape {
                        appearance PBRAppearance {
                          baseColor 0 0 0
                          roughness 1
                          metalness 0
                        }
                        geometry Cylinder {
                          height 0.005
                          radius 0.016
                        }
                      }
                    ]
                  }
                  DEF TIRE Shape {
                    appearance PBRAppearance {
                      baseColorMap ImageTexture {
                        url [
                          "https://raw.githubusercontent.com/cyberbotics/webots/R2025a/projects/appearances/protos/textures/asphalt/asphalt_base_color.jpg"
                        ]
                        filtering 5
                      }
                      roughnessMap ImageTexture {
                        url [
                          "https://raw.githubusercontent.com/cyberbotics/webots/R2025a/projects/appearances/protos/textures/asphalt/asphalt_roughness.jpg"
                        ]
                        filtering 5
                      }
                      metalness 0
                      IBLStrength 0.5
                      normalMap ImageTexture {
                        url [
                          "https://raw.githubusercontent.com/cyberbotics/webots/R2025a/projects/appearances/protos/textures/asphalt/asphalt_normal.jpg"
                        ]
                        filtering 5
                      }
                      normalMapFactor 1.5
                      occlusionMap ImageTexture {
                        url [
                          "https://raw.githubusercontent.com/cyberbotics/webots/R2025a/projects/appearances/protos/textures/asphalt/asphalt_occlusion.jpg"
                        ]
                        filtering 5
                      }
                      textureTransform TextureTransform {
                        scale 25 25
                      }
                    }
                    geometry Mesh {
                      url [
                        "https://raw.githubusercontent.com/cyberbotics/webots/R2025a/projects/robots/pal_robotics/tiago_base/protos/meshes/tire.obj"
                      ]
                    }
                  }
                  DEF RIM Shape {
                    appearance PBRAppearance {
                      baseColorMap ImageTexture {
                        url [
                          "https://raw.githubusercontent.com/cyberbotics/webots/R2025a/projects/robots/pal_robotics/tiago_base/protos/textures/metal_stainless_clean_base_color.jpg"
                        ]
                      }
                      roughnessMap ImageTexture {
                        url [
                          "https://raw.githubusercontent.com/cyberbotics/webots/R2025a/projects/robots/pal_robotics/tiago_base/protos/textures/metal_stainless_clean_roughness.jpg"
                        ]
                      }
                      metalness 0.9
                      textureTransform TextureTransform {
                        scale 10 10
                      }
                    }
                    geometry Mesh {
                      url [
                        "https://raw.githubusercontent.com/cyberbotics/webots/R2025a/projects/robots/pal_robotics/tiago_base/protos/meshes/rim.obj"
                      ]
                    }
                  }
                ]
              }
            ]
          }
        ]
        name "wheel_left_link"
        boundingObject Pose {
          children [
            Cylinder {
              height 0.04
              radius 0.0985
            }
          ]
        }
        physics Physics {
          density -1
          mass 1.82362
        }
        linearVelocity 0.0985253427704839 -0.00022350268619436846 -0.00013174983956911493
        angularVelocity -0.00021097710244262822 1.0001144445383128 3.963720805762633e-05
      }
    }
    DEF CASTER_WHEEL_FRONT_RIGHT_JOINT HingeJoint {
      jointParameters HingeJointParameters {
        position 6.272986530789733
        axis 0 0 1
        anchor 0.1695 -0.102 -0.0335
        suspensionSpringConstant 250000
        suspensionAxis 0 0 1
      }
      endPoint DEF CASTER_WHEEL_FRONT_RIGHT Solid {
        translation 0.1695 -0.102 -0.0335
        rotation 0 0 1 6.272986530789718
        children [
          DEF SMALL_WHEEL_JOINT HingeJoint {
            jointParameters HingeJointParameters {
              position 1446.7979390829908
              axis 0 1 0
              anchor -0.016 0 -0.04
            }
            endPoint DEF SMALL_WHEEL Solid {
              translation -0.016 0 -0.04
              rotation -0.5409863467030215 0.5946978957840862 0.5947000802344813 2.1498025056921675
              children [
                DEF SMALL_WHEEL_SHAPE Shape {
                  appearance PBRAppearance {
                    baseColorMap ImageTexture {
                      url [
                        "https://raw.githubusercontent.com/cyberbotics/webots/R2025a/projects/appearances/protos/textures/asphalt/asphalt_base_color.jpg"
                      ]
                      filtering 5
                    }
                    roughnessMap ImageTexture {
                      url [
                        "https://raw.githubusercontent.com/cyberbotics/webots/R2025a/projects/appearances/protos/textures/asphalt/asphalt_roughness.jpg"
                      ]
                      filtering 5
                    }
                    metalness 0
                    IBLStrength 0.5
                    normalMap ImageTexture {
                      url [
                        "https://raw.githubusercontent.com/cyberbotics/webots/R2025a/projects/appearances/protos/textures/asphalt/asphalt_normal.jpg"
                      ]
                      filtering 5
                    }
                    normalMapFactor 1.5
                    occlusionMap ImageTexture {
                      url [
                        "https://raw.githubusercontent.com/cyberbotics/webots/R2025a/projects/appearances/protos/textures/asphalt/asphalt_occlusion.jpg"
                      ]
                      filtering 5
                    }
                    textureTransform TextureTransform {
                      scale 25 25
                    }
                  }
                  geometry Mesh {
                    url [
                      "https://raw.githubusercontent.com/cyberbotics/webots/R2025a/projects/robots/pal_robotics/tiago_base/protos/meshes/small_wheel_shape.obj"
                    ]
                  }
                }
              ]
              name "caster_front_right_2_link"
              boundingObject DEF SMALL_WHEEL_BO Pose {
                children [
                  Cylinder {
                    height 0.015
                    radius 0.025
                  }
                ]
              }
              physics DEF SMALL_WHEEL_PHYSIC Physics {
                density -1
                mass 0.088558
              }
              linearVelocity 0.09853211902153806 -0.0009857149422961666 4.4236181538904746e-05
              angularVelocity 0.044843721210472066 3.9386589768883904 0.048466048097003056
            }
          }
          DEF CASTER_SUPPORT Shape {
            appearance PBRAppearance {
              baseColorMap ImageTexture {
                url [
                  "https://raw.githubusercontent.com/cyberbotics/webots/R2025a/projects/appearances/protos/textures/brushed_aluminium/brushed_aluminium_base_color.jpg"
                ]
              }
              roughnessMap ImageTexture {
                url [
                  "https://raw.githubusercontent.com/cyberbotics/webots/R2025a/projects/appearances/protos/textures/brushed_aluminium/brushed_aluminium_roughness.jpg"
                ]
              }
              normalMap ImageTexture {
                url [
                  "https://raw.githubusercontent.com/cyberbotics/webots/R2025a/projects/appearances/protos/textures/brushed_aluminium/brushed_aluminium_normal.jpg"
                ]
              }
              textureTransform TextureTransform {
                rotation -1.57
                scale 2 2
              }
            }
            geometry Mesh {
              url [
                "https://raw.githubusercontent.com/cyberbotics/webots/R2025a/projects/robots/pal_robotics/tiago_base/protos/meshes/caster_support.obj"
              ]
            }
          }
        ]
        name "caster_front_right_1_link"
        boundingObject DEF CASTER_WHEEL_BO Pose {
          translation -0.003 0 -0.022
          children [
            DEF CASTER_SUPPORT_BO Box {
              size 0.036 0.032 0.04
            }
          ]
        }
        physics DEF CASTER_WHEEL_PHYSIC Physics {
          density -1
          mass 0.051448
        }
        linearVelocity 0.09851799547396757 -0.00041109333255145395 4.373132953769003e-05
        angularVelocity -0.0005325377219934238 0.00011168845488106583 0.04242444122730783
      }
    }
    DEF CASTER_WHEEL_FRONT_LEFT_JOINT HingeJoint {
      jointParameters HingeJointParameters {
        position -0.010918589849762524
        axis 0 0 1
        anchor 0.1695 0.102 -0.0335
        suspensionSpringConstant 250000
        suspensionAxis 0 0 1
      }
      endPoint DEF CASTER_WHEEL_FRONT_LEFT Solid {
        translation 0.1695 0.102 -0.0335
        rotation 0 0 -1 0.010918589849782846
        children [
          DEF SMALL_WHEEL_JOINT HingeJoint {
            jointParameters HingeJointParameters {
              position 1483.3845795396983
              axis 0 1 0
              anchor -0.016 0 -0.04
            }
            endPoint DEF SMALL_WHEEL Solid {
              translation -0.016 0 -0.04
              rotation -0.9280947332974723 0.2632865898342117 0.2632875569391104 1.6453523009175581
              children [
                DEF SMALL_WHEEL_SHAPE Shape {
                  appearance PBRAppearance {
                    baseColorMap ImageTexture {
                      url [
                        "https://raw.githubusercontent.com/cyberbotics/webots/R2025a/projects/appearances/protos/textures/asphalt/asphalt_base_color.jpg"
                      ]
                      filtering 5
                    }
                    roughnessMap ImageTexture {
                      url [
                        "https://raw.githubusercontent.com/cyberbotics/webots/R2025a/projects/appearances/protos/textures/asphalt/asphalt_roughness.jpg"
                      ]
                      filtering 5
                    }
                    metalness 0
                    IBLStrength 0.5
                    normalMap ImageTexture {
                      url [
                        "https://raw.githubusercontent.com/cyberbotics/webots/R2025a/projects/appearances/protos/textures/asphalt/asphalt_normal.jpg"
                      ]
                      filtering 5
                    }
                    normalMapFactor 1.5
                    occlusionMap ImageTexture {
                      url [
                        "https://raw.githubusercontent.com/cyberbotics/webots/R2025a/projects/appearances/protos/textures/asphalt/asphalt_occlusion.jpg"
                      ]
                      filtering 5
                    }
                    textureTransform TextureTransform {
                      scale 25 25
                    }
                  }
                  geometry Mesh {
                    url [
                      "https://raw.githubusercontent.com/cyberbotics/webots/R2025a/projects/robots/pal_robotics/tiago_base/protos/meshes/small_wheel_shape.obj"
                    ]
                  }
                }
              ]
              name "caster_front_left_2_link"
              boundingObject DEF SMALL_WHEEL_BO Pose {
                children [
                  Cylinder {
                    height 0.015
                    radius 0.025
                  }
                ]
              }
              physics DEF SMALL_WHEEL_PHYSIC Physics {
                density -1
                mass 0.088558
              }
              linearVelocity 0.0985541824532825 -0.0010633248992435354 -8.349533841939232e-05
              angularVelocity 0.04793412078739804 3.938019015426931 0.053597203553230145
            }
          }
          DEF CASTER_SUPPORT Shape {
            appearance PBRAppearance {
              baseColorMap ImageTexture {
                url [
                  "https://raw.githubusercontent.com/cyberbotics/webots/R2025a/projects/appearances/protos/textures/brushed_aluminium/brushed_aluminium_base_color.jpg"
                ]
              }
              roughnessMap ImageTexture {
                url [
                  "https://raw.githubusercontent.com/cyberbotics/webots/R2025a/projects/appearances/protos/textures/brushed_aluminium/brushed_aluminium_roughness.jpg"
                ]
              }
              normalMap ImageTexture {
                url [
                  "https://raw.githubusercontent.com/cyberbotics/webots/R2025a/projects/appearances/protos/textures/brushed_aluminium/brushed_aluminium_normal.jpg"
                ]
              }
              textureTransform TextureTransform {
                rotation -1.57
                scale 2 2
              }
            }
            geometry Mesh {
              url [
                "https://raw.githubusercontent.com/cyberbotics/webots/R2025a/projects/robots/pal_robotics/tiago_base/protos/meshes/caster_support.obj"
              ]
            }
          }
        ]
        name "caster_front_left_1_link"
        boundingObject DEF CASTER_WHEEL_BO Pose {
          translation -0.003 0 -0.022
          children [
            DEF CASTER_SUPPORT_BO Box {
              size 0.036 0.032 0.04
            }
          ]
        }
        physics DEF CASTER_WHEEL_PHYSIC Physics {
          density -1
          mass 0.051448
        }
        linearVelocity 0.09853895683939821 -0.00042637755507145454 -8.654959613648512e-05
        angularVelocity -0.0005200588311145824 0.00011165750021199817 0.04701434451036318
      }
    }
    DEF CASTER_WHEEL_BACK_RIGHT_JOINT HingeJoint {
      jointParameters HingeJointParameters {
        position -6.300893352993082
        axis 0 0 1
        anchor -0.1735 -0.102 -0.0335
        suspensionSpringConstant 250000
        suspensionAxis 0 0 1
      }
      endPoint DEF CASTER_WHEEL_BACK_RIGHT Solid {
        translation -0.1735 -0.102 -0.0335
        rotation 0 0 1 6.2654772613660965
        children [
          DEF SMALL_WHEEL_JOINT HingeJoint {
            jointParameters HingeJointParameters {
              position 1382.808723364624
              axis 0 1 0
              anchor -0.016 0 -0.04
            }
            endPoint DEF SMALL_WHEEL_JOINT Solid {
              translation -0.016 0 -0.04
              rotation -0.9387429964151984 0.24368129846764275 0.24368219356066662 1.6339714714547044
              children [
                DEF SMALL_WHEEL_SHAPE Shape {
                  appearance PBRAppearance {
                    baseColorMap ImageTexture {
                      url [
                        "https://raw.githubusercontent.com/cyberbotics/webots/R2025a/projects/appearances/protos/textures/asphalt/asphalt_base_color.jpg"
                      ]
                      filtering 5
                    }
                    roughnessMap ImageTexture {
                      url [
                        "https://raw.githubusercontent.com/cyberbotics/webots/R2025a/projects/appearances/protos/textures/asphalt/asphalt_roughness.jpg"
                      ]
                      filtering 5
                    }
                    metalness 0
                    IBLStrength 0.5
                    normalMap ImageTexture {
                      url [
                        "https://raw.githubusercontent.com/cyberbotics/webots/R2025a/projects/appearances/protos/textures/asphalt/asphalt_normal.jpg"
                      ]
                      filtering 5
                    }
                    normalMapFactor 1.5
                    occlusionMap ImageTexture {
                      url [
                        "https://raw.githubusercontent.com/cyberbotics/webots/R2025a/projects/appearances/protos/textures/asphalt/asphalt_occlusion.jpg"
                      ]
                      filtering 5
                    }
                    textureTransform TextureTransform {
                      scale 25 25
                    }
                  }
                  geometry Mesh {
                    url [
                      "https://raw.githubusercontent.com/cyberbotics/webots/R2025a/projects/robots/pal_robotics/tiago_base/protos/meshes/small_wheel_shape.obj"
                    ]
                  }
                }
              ]
              name "caster_back_right_2_link"
              boundingObject DEF SMALL_WHEEL_BO Pose {
                children [
                  Cylinder {
                    height 0.015
                    radius 0.025
                  }
                ]
              }
              physics DEF SMALL_WHEEL_PHYSIC Physics {
                density -1
                mass 0.088558
              }
              linearVelocity 0.09854583115574114 -0.001811058247482078 8.168831942480146e-05
              angularVelocity 0.07681766527290035 3.920175523260509 0.10655314042981422
            }
          }
          DEF CASTER_SUPPORT Shape {
            appearance PBRAppearance {
              baseColorMap ImageTexture {
                url [
                  "https://raw.githubusercontent.com/cyberbotics/webots/R2025a/projects/appearances/protos/textures/brushed_aluminium/brushed_aluminium_base_color.jpg"
                ]
              }
              roughnessMap ImageTexture {
                url [
                  "https://raw.githubusercontent.com/cyberbotics/webots/R2025a/projects/appearances/protos/textures/brushed_aluminium/brushed_aluminium_roughness.jpg"
                ]
              }
              normalMap ImageTexture {
                url [
                  "https://raw.githubusercontent.com/cyberbotics/webots/R2025a/projects/appearances/protos/textures/brushed_aluminium/brushed_aluminium_normal.jpg"
                ]
              }
              textureTransform TextureTransform {
                rotation -1.57
                scale 2 2
              }
            }
            geometry Mesh {
              url [
                "https://raw.githubusercontent.com/cyberbotics/webots/R2025a/projects/robots/pal_robotics/tiago_base/protos/meshes/caster_support.obj"
              ]
            }
          }
        ]
        name "caster_back_right_1_link"
        boundingObject DEF CASTER_WHEEL_BO Pose {
          translation -0.003 0 -0.022
          children [
            DEF CASTER_SUPPORT_BO Box {
              size 0.036 0.032 0.04
            }
          ]
        }
        physics DEF CASTER_WHEEL_PHYSIC Physics {
          density -1
          mass 0.051448
        }
        linearVelocity 0.09852300291259915 -0.0005373317680900381 8.201182521407966e-05
        angularVelocity -0.00038987231019657566 0.00010997460218701214 0.09495924459170738
      }
    }
    DEF CASTER_WHEEL_BACK_LEFT_JOINT HingeJoint {
      jointParameters HingeJointParameters {
        position -0.02942717722731893
        axis 0 0 1
        anchor -0.1735 0.102 -0.0335
        suspensionSpringConstant 250000
        suspensionAxis 0 0 1
      }
      endPoint DEF CASTER_WHEEL_BACK_LEFT Solid {
        translation -0.1735 0.102 -0.0335
        rotation 0 0 -1 0.029427177227325383
        children [
          DEF SMALL_WHEEL_JOINT HingeJoint {
            jointParameters HingeJointParameters {
              position 1417.5353745808177
              axis 0 1 0
              anchor -0.016 0 -0.04
            }
            endPoint DEF SMALL_WHEEL Solid {
              translation -0.016 0 -0.04
              rotation -0.24159696198965291 -0.6861586730319508 -0.6861611934381036 2.6674854919512017
              children [
                DEF SMALL_WHEEL_SHAPE Shape {
                  appearance PBRAppearance {
                    baseColorMap ImageTexture {
                      url [
                        "https://raw.githubusercontent.com/cyberbotics/webots/R2025a/projects/appearances/protos/textures/asphalt/asphalt_base_color.jpg"
                      ]
                      filtering 5
                    }
                    roughnessMap ImageTexture {
                      url [
                        "https://raw.githubusercontent.com/cyberbotics/webots/R2025a/projects/appearances/protos/textures/asphalt/asphalt_roughness.jpg"
                      ]
                      filtering 5
                    }
                    metalness 0
                    IBLStrength 0.5
                    normalMap ImageTexture {
                      url [
                        "https://raw.githubusercontent.com/cyberbotics/webots/R2025a/projects/appearances/protos/textures/asphalt/asphalt_normal.jpg"
                      ]
                      filtering 5
                    }
                    normalMapFactor 1.5
                    occlusionMap ImageTexture {
                      url [
                        "https://raw.githubusercontent.com/cyberbotics/webots/R2025a/projects/appearances/protos/textures/asphalt/asphalt_occlusion.jpg"
                      ]
                      filtering 5
                    }
                    textureTransform TextureTransform {
                      scale 25 25
                    }
                  }
                  geometry Mesh {
                    url [
                      "https://raw.githubusercontent.com/cyberbotics/webots/R2025a/projects/robots/pal_robotics/tiago_base/protos/meshes/small_wheel_shape.obj"
                    ]
                  }
                }
              ]
              name "caster_back_left_2_link"
              boundingObject DEF SMALL_WHEEL_BO Pose {
                children [
                  Cylinder {
                    height 0.015
                    radius 0.025
                  }
                ]
              }
              physics DEF SMALL_WHEEL_PHYSIC Physics {
                density -1
                mass 0.088558
              }
              linearVelocity 0.09855980804463715 -0.0030251949450121663 -4.623329413968317e-05
              angularVelocity 0.125352666263753 3.8975720052637253 0.1861676856335801
            }
          }
          DEF CASTER_SUPPORT Shape {
            appearance PBRAppearance {
              baseColorMap ImageTexture {
                url [
                  "https://raw.githubusercontent.com/cyberbotics/webots/R2025a/projects/appearances/protos/textures/brushed_aluminium/brushed_aluminium_base_color.jpg"
                ]
              }
              roughnessMap ImageTexture {
                url [
                  "https://raw.githubusercontent.com/cyberbotics/webots/R2025a/projects/appearances/protos/textures/brushed_aluminium/brushed_aluminium_roughness.jpg"
                ]
              }
              normalMap ImageTexture {
                url [
                  "https://raw.githubusercontent.com/cyberbotics/webots/R2025a/projects/appearances/protos/textures/brushed_aluminium/brushed_aluminium_normal.jpg"
                ]
              }
              textureTransform TextureTransform {
                rotation -1.57
                scale 2 2
              }
            }
            geometry Mesh {
              url [
                "https://raw.githubusercontent.com/cyberbotics/webots/R2025a/projects/robots/pal_robotics/tiago_base/protos/meshes/caster_support.obj"
              ]
            }
          }
        ]
        name "caster_back_left_1_link"
        boundingObject DEF CASTER_WHEEL_BO Pose {
          translation -0.003 0 -0.022
          children [
            DEF CASTER_SUPPORT_BO Box {
              size 0.036 0.032 0.04
            }
          ]
        }
        physics DEF CASTER_WHEEL_PHYSIC Physics {
          density -1
          mass 0.051448
        }
        linearVelocity 0.0985454468173619 -0.0007662274439229827 -4.8349652832759545e-05
        angularVelocity -0.000192072744923322 0.00010544328198667652 0.16854954203770295
      }
    }
  ]
  name "TIAGo Base"
  model "PAL Robotics - TIAGo Base"
  boundingObject Group {
    children [
      DEF BASE_BO Pose {
        translation 0 0 0.06
        children [
          Shape {
            geometry Cylinder {
              height 0.276
              radius 0.265
            }
          }
        ]
      }
      DEF ANTENNA_LEFT_BO Pose {
        translation -0.201 0.1062 0.28
        children [
          DEF ANTENNA_BO Cylinder {
            height 0.173
            radius 0.007
          }
        ]
      }
      DEF ANTENNA_RIGHT_BO Pose {
        translation -0.201 -0.1062 0.28
        children [
          USE ANTENNA_BO
        ]
      }
    ]
  }
  physics Physics {
    density -1
    mass 28.26649
  }
  controller "tiago_base_controller"
  controllerArgs [
    ""
  ]
  linearVelocity 0.09853246992503958 -0.00018784434436475638 -2.7446172822724335e-06
  angularVelocity -0.0006516327206667695 0.00011175805053931833 -0.0001002143254947369
}
