#VRML_SIM R2025a utf8

EXTERNPROTO "https://raw.githubusercontent.com/cyberbotics/webots/R2025a/projects/objects/backgrounds/protos/TexturedBackground.proto"
EXTERNPROTO "https://raw.githubusercontent.com/cyberbotics/webots/R2025a/projects/objects/backgrounds/protos/TexturedBackgroundLight.proto"
EXTERNPROTO "https://raw.githubusercontent.com/cyberbotics/webots/R2025a/projects/objects/floors/protos/RectangleArena.proto"

WorldInfo {
}
Viewpoint {
  orientation 0.3404077828105003 0.46287952383143455 -0.8184528623076736 1.464008461958331
  position -1.4487317797698434 4.6578794553771115 5.750901392745832
}
TexturedBackground {
}
TexturedBackgroundLight {
}
RectangleArena {
  floorSize 5 5
  wallHeight 0.3
}
Robot {
  translation 0.002726049210985137 -0.023355677249792754 0.09400836898973967
  rotation 0.00013393411916316208 -1.604527929734918e-05 -0.9999999909021003 -2.954600291054434
  children [
    DEF BODY_EXTENSION Pose {
    }
    DEF LIDAR Pose {
      translation 0.202 0 -0.004
    }
    Accelerometer {
    }
    InertialUnit {
    }
    Gyro {
    }
    Solid {
      translation 0 0 -0.095
      name "base_footprint"
    }
    DEF BASE_MOBILE_SHAPE Group {
      children [
        DEF BASE Shape {
          appearance PBRAppearance {
            baseColor 0.823529 0.776471 0.776471
            baseColorMap ImageTexture {
              url [
                "https://raw.githubusercontent.com/cyberbotics/webots/R2025a/projects/appearances/protos/textures/matte_car_paint/matte_car_paint_base_color.jpg"
              ]
              filtering 5
            }
            roughnessMap ImageTexture {
              url [
                "https://raw.githubusercontent.com/cyberbotics/webots/R2025a/projects/appearances/protos/textures/glossy_car_paint/glossy_car_paint_roughness.jpg"
              ]
              filtering 5
            }
            metalness 0
            IBLStrength 1.8
            normalMap ImageTexture {
              url [
                "https://raw.githubusercontent.com/cyberbotics/webots/R2025a/projects/appearances/protos/textures/glossy_car_paint/glossy_car_paint_normal.jpg"
              ]
              filtering 5
            }
            normalMapFactor 0.5
            textureTransform TextureTransform {
              scale 4 4
            }
          }
          geometry Mesh {
            url [
              "https://raw.githubusercontent.com/cyberbotics/webots/R2025a/projects/robots/pal_robotics/tiago_base/protos/meshes/base.obj"
            ]
          }
        }
        DEF ANTENNA_LEFT Pose {
          translation -0.201 0.1062 0.195
          children [
            DEF ANTENNA_SHAPE Shape {
              appearance PBRAppearance {
                baseColor 0.133333 0.133333 0.133333
                baseColorMap ImageTexture {
                  url [
                    "https://raw.githubusercontent.com/cyberbotics/webots/R2025a/projects/appearances/protos/textures/matte_car_paint/matte_car_paint_base_color.jpg"
                  ]
                  filtering 5
                }
                roughnessMap ImageTexture {
                  url [
                    "https://raw.githubusercontent.com/cyberbotics/webots/R2025a/projects/appearances/protos/textures/matte_car_paint/matte_car_paint_roughness.jpg"
                  ]
                  filtering 5
                }
                metalness 0
                normalMapFactor 0.5
                textureTransform TextureTransform {
                  scale 10 10
                }
              }
              geometry Mesh {
                url [
                  "https://raw.githubusercontent.com/cyberbotics/webots/R2025a/projects/robots/pal_robotics/tiago_base/protos/meshes/antenna_shape.obj"
                ]
              }
            }
          ]
        }
        DEF ANTENNA_RIGHT Pose {
          translation -0.201 -0.1062 0.195
          children [
            USE ANTENNA_SHAPE
          ]
        }
      ]
    }
    DEF FRONT_SENSOR_1 Pose {
      translation 0.1714 -0.111 0.002
      rotation 0.47980308243485 -0.620398662991083 0.620398662994121 -2.246872814929654
      children [
        Shape {
          appearance PBRAppearance {
            baseColor 0 0 0
          }
          geometry Cylinder {
            height 0.01
            radius 0.01
          }
        }
      ]
      translationStep 0.001
      rotationStep 0.001
    }
    DEF FRONT_SENSOR_2 Pose {
      translation 0.1714 0.111 0.002
      rotation 0.47980308243485 0.620398662991083 0.620398662994121 2.246872814929654
      children [
        Shape {
          appearance PBRAppearance {
            baseColor 0 0 0
          }
          geometry Cylinder {
            height 0.01
            radius 0.01
          }
        }
      ]
      rotationStep 0.001
    }
    DEF BUMPER TouchSensor {
      translation -0.001086502586027411 3.295727169712326e-05 0.029397734362156133
      rotation 0.03169395615718809 -0.9344699042212348 -0.35462866670344445 -3.182807216006722e-05
      children [
        DEF BUMPER_SHAPE Shape {
          appearance PBRAppearance {
            baseColor 1 0.552941 0.184314
            transparency 0.01
            roughness 0.1
            metalness 0
          }
          geometry Mesh {
            url [
              "https://raw.githubusercontent.com/cyberbotics/webots/R2025a/projects/robots/pal_robotics/tiago_base/protos/meshes/bumper_shape.obj"
            ]
          }
        }
      ]
      name "base_cover_link"
      boundingObject Pose {
        translation 0 0 0.043
        children [
          Cylinder {
            height 0.086
            radius 0.272
          }
        ]
      }
      physics Physics {
        density -1
        mass 0.25821
      }
      linearVelocity -0.0001938946123167188 -0.0009279067865831092 1.484484033912597e-07
      angularVelocity -8.84380949449589e-07 -1.6320544008575965e-06 -0.8884952977953497
    }
    DEF DISTANCE_SENSOR_BACK_LEFT DistanceSensor {
      translation -0.183 0.183 0.173
      rotation 0 0 1 2.3562
      children [
        DEF DS_SHAPE Group {
          children [
            DEF DS_SH_1 Pose {
              translation 0 -0.0115 0
              rotation 0 0 1 -1.5707896938995747
              children [
                Shape {
                  appearance PBRAppearance {
                    baseColor 0 0 0
                    baseColorMap ImageTexture {
                      url [
                        "https://raw.githubusercontent.com/cyberbotics/webots/R2025a/projects/appearances/protos/textures/matte_car_paint/matte_car_paint_base_color.jpg"
                      ]
                      filtering 5
                    }
                    roughnessMap ImageTexture {
                      url [
                        "https://raw.githubusercontent.com/cyberbotics/webots/R2025a/projects/appearances/protos/textures/matte_car_paint/matte_car_paint_roughness.jpg"
                      ]
                      filtering 5
                    }
                    metalness 0
                    normalMapFactor 0.5
                    textureTransform TextureTransform {
                      scale 10 10
                    }
                  }
                }
              ]
            }
            DEF DS_SH_2 Pose {
              translation 0 0.0115 0
              rotation 0 0 1 -1.5707896938995747
              children [
                Shape {
                  appearance PBRAppearance {
                    baseColor 0 0 0
                    baseColorMap ImageTexture {
                      url [
                        "https://raw.githubusercontent.com/cyberbotics/webots/R2025a/projects/appearances/protos/textures/matte_car_paint/matte_car_paint_base_color.jpg"
                      ]
                      filtering 5
                    }
                    roughnessMap ImageTexture {
                      url [
                        "https://raw.githubusercontent.com/cyberbotics/webots/R2025a/projects/appearances/protos/textures/matte_car_paint/matte_car_paint_roughness.jpg"
                      ]
                      filtering 5
                    }
                    metalness 0
                    normalMapFactor 0.5
                    textureTransform TextureTransform {
                      scale 10 10
                    }
                  }
                }
              ]
            }
          ]
        }
      ]
      name "base_sonar_03_link"
    }
    DEF DISTANCE_SENSOR_BACK_MIDDLE DistanceSensor {
      translation -0.259 0 0.173
      rotation 0 0 1 3.1416
      children [
        USE DS_SHAPE
      ]
      name "base_sonar_02_link"
    }
    DEF DISTANCE_SENSOR_BACK_RIGHT DistanceSensor {
      translation -0.183 -0.183 0.173
      rotation 0 0 1 3.927
      children [
        USE DS_SHAPE
      ]
      name "base_sonar_01_link"
    }
    DEF RIGHT_WHEEL_JOINT HingeJoint {
      jointParameters HingeJointParameters {
        position 333.7515368967127
        axis 0 1 0
        anchor 0 -0.2022 0
        suspensionAxis 0 0 1
      }
      device [
        RotationalMotor {
          name "wheel_right_joint"
          acceleration 5.0762
          maxVelocity 10.1523
        }
        PositionSensor {
          name "wheel_right_joint_sensor"
        }
      ]
      endPoint DEF RIGHT_WHEEL Solid {
        translation 0 -0.202 0
        rotation -0.8759455345670225 -0.3411147648856131 0.3411160178724039 4.5803195578776785
        children [
          DEF BIG_WHEEL Group {
            children [
              Pose {
                translation 0 0 0.042
                children [
                  Shape {
                    appearance PBRAppearance {
                      baseColor 0 0 0
                      roughness 1
                      metalness 0
                    }
                    geometry Cylinder {
                      height 0.005
                      radius 0.016
                    }
                  }
                ]
              }
              DEF TIRE Shape {
                appearance PBRAppearance {
                  baseColorMap ImageTexture {
                    url [
                      "https://raw.githubusercontent.com/cyberbotics/webots/R2025a/projects/appearances/protos/textures/asphalt/asphalt_base_color.jpg"
                    ]
                    filtering 5
                  }
                  roughnessMap ImageTexture {
                    url [
                      "https://raw.githubusercontent.com/cyberbotics/webots/R2025a/projects/appearances/protos/textures/asphalt/asphalt_roughness.jpg"
                    ]
                    filtering 5
                  }
                  metalness 0
                  IBLStrength 0.5
                  normalMap ImageTexture {
                    url [
                      "https://raw.githubusercontent.com/cyberbotics/webots/R2025a/projects/appearances/protos/textures/asphalt/asphalt_normal.jpg"
                    ]
                    filtering 5
                  }
                  normalMapFactor 1.5
                  occlusionMap ImageTexture {
                    url [
                      "https://raw.githubusercontent.com/cyberbotics/webots/R2025a/projects/appearances/protos/textures/asphalt/asphalt_occlusion.jpg"
                    ]
                    filtering 5
                  }
                  textureTransform TextureTransform {
                    scale 25 25
                  }
                }
                geometry Mesh {
                  url [
                    "https://raw.githubusercontent.com/cyberbotics/webots/R2025a/projects/robots/pal_robotics/tiago_base/protos/meshes/tire.obj"
                  ]
                }
              }
              DEF RIM Shape {
                appearance PBRAppearance {
                  baseColorMap ImageTexture {
                    url [
                      "https://raw.githubusercontent.com/cyberbotics/webots/R2025a/projects/robots/pal_robotics/tiago_base/protos/textures/metal_stainless_clean_base_color.jpg"
                    ]
                  }
                  roughnessMap ImageTexture {
                    url [
                      "https://raw.githubusercontent.com/cyberbotics/webots/R2025a/projects/robots/pal_robotics/tiago_base/protos/textures/metal_stainless_clean_roughness.jpg"
                    ]
                  }
                  metalness 0.9
                  textureTransform TextureTransform {
                    scale 10 10
                  }
                }
                geometry Mesh {
                  url [
                    "https://raw.githubusercontent.com/cyberbotics/webots/R2025a/projects/robots/pal_robotics/tiago_base/protos/meshes/rim.obj"
                  ]
                }
              }
            ]
          }
        ]
        name "wheel_right_link"
        boundingObject Pose {
          children [
            Cylinder {
              height 0.04
              radius 0.0985
            }
          ]
        }
        physics Physics {
          density -1
          mass 1.82362
        }
        linearVelocity 0.17713461264469865 -0.031001289108739796 3.071884505258356e-08
        angularVelocity 0.34124555003103973 1.9708292625394306 -0.8967601327815696
      }
    }
    DEF LEFT_WHEEL_JOINT HingeJoint {
      jointParameters HingeJointParameters {
        position 5457.8539819228745
        axis 0 1 0
        anchor 0 0.2022 0
        suspensionAxis 0 0 1
      }
      device [
        RotationalMotor {
          name "wheel_left_joint"
          acceleration 5.0762
          maxVelocity 10.1523
        }
        PositionSensor {
          name "wheel_left_joint_sensor"
        }
      ]
      endPoint DEF LEFT_WHEEL Solid {
        translation 0 0.202 0
        rotation -0.3260241094509402 0.6684702675822335 -0.668472723015127 3.7719062726740904
        children [
          Pose {
            rotation -1 0 0 3.141593
            children [
              DEF BIG_WHEEL Group {
                children [
                  Pose {
                    translation 0 0 0.042
                    children [
                      Shape {
                        appearance PBRAppearance {
                          baseColor 0 0 0
                          roughness 1
                          metalness 0
                        }
                        geometry Cylinder {
                          height 0.005
                          radius 0.016
                        }
                      }
                    ]
                  }
                  DEF TIRE Shape {
                    appearance PBRAppearance {
                      baseColorMap ImageTexture {
                        url [
                          "https://raw.githubusercontent.com/cyberbotics/webots/R2025a/projects/appearances/protos/textures/asphalt/asphalt_base_color.jpg"
                        ]
                        filtering 5
                      }
                      roughnessMap ImageTexture {
                        url [
                          "https://raw.githubusercontent.com/cyberbotics/webots/R2025a/projects/appearances/protos/textures/asphalt/asphalt_roughness.jpg"
                        ]
                        filtering 5
                      }
                      metalness 0
                      IBLStrength 0.5
                      normalMap ImageTexture {
                        url [
                          "https://raw.githubusercontent.com/cyberbotics/webots/R2025a/projects/appearances/protos/textures/asphalt/asphalt_normal.jpg"
                        ]
                        filtering 5
                      }
                      normalMapFactor 1.5
                      occlusionMap ImageTexture {
                        url [
                          "https://raw.githubusercontent.com/cyberbotics/webots/R2025a/projects/appearances/protos/textures/asphalt/asphalt_occlusion.jpg"
                        ]
                        filtering 5
                      }
                      textureTransform TextureTransform {
                        scale 25 25
                      }
                    }
                    geometry Mesh {
                      url [
                        "https://raw.githubusercontent.com/cyberbotics/webots/R2025a/projects/robots/pal_robotics/tiago_base/protos/meshes/tire.obj"
                      ]
                    }
                  }
                  DEF RIM Shape {
                    appearance PBRAppearance {
                      baseColorMap ImageTexture {
                        url [
                          "https://raw.githubusercontent.com/cyberbotics/webots/R2025a/projects/robots/pal_robotics/tiago_base/protos/textures/metal_stainless_clean_base_color.jpg"
                        ]
                      }
                      roughnessMap ImageTexture {
                        url [
                          "https://raw.githubusercontent.com/cyberbotics/webots/R2025a/projects/robots/pal_robotics/tiago_base/protos/textures/metal_stainless_clean_roughness.jpg"
                        ]
                      }
                      metalness 0.9
                      textureTransform TextureTransform {
                        scale 10 10
                      }
                    }
                    geometry Mesh {
                      url [
                        "https://raw.githubusercontent.com/cyberbotics/webots/R2025a/projects/robots/pal_robotics/tiago_base/protos/meshes/rim.obj"
                      ]
                    }
                  }
                ]
              }
            ]
          }
        ]
        name "wheel_left_link"
        boundingObject Pose {
          children [
            Cylinder {
              height 0.04
              radius 0.0985
            }
          ]
        }
        physics Physics {
          density -1
          mass 1.82362
        }
        linearVelocity -0.17713951037449277 0.031000761176968077 2.6133706586776903e-07
        angularVelocity -0.34124737539904637 -1.9708332057753595 -0.896732575269964
      }
    }
    DEF CASTER_WHEEL_FRONT_RIGHT_JOINT HingeJoint {
      jointParameters HingeJointParameters {
        position 23.12449436854477
        axis 0 0 1
        anchor 0.1695 -0.102 -0.0335
        suspensionSpringConstant 250000
        suspensionAxis 0 0 1
      }
      endPoint DEF CASTER_WHEEL_FRONT_RIGHT Solid {
        translation 0.1695 -0.102 -0.0335
        rotation 0 0 -1 2.0082468601735757
        children [
          DEF SMALL_WHEEL_JOINT HingeJoint {
            jointParameters HingeJointParameters {
              position 14530.457403056802
              axis 0 1 0
              anchor -0.016 0 -0.04
            }
            endPoint DEF SMALL_WHEEL Solid {
              translation -0.016 0 -0.04
              rotation 0.21056989296425796 0.6912513326709367 0.6912538717849434 3.5566670799698237
              children [
                DEF SMALL_WHEEL_SHAPE Shape {
                  appearance PBRAppearance {
                    baseColorMap ImageTexture {
                      url [
                        "https://raw.githubusercontent.com/cyberbotics/webots/R2025a/projects/appearances/protos/textures/asphalt/asphalt_base_color.jpg"
                      ]
                      filtering 5
                    }
                    roughnessMap ImageTexture {
                      url [
                        "https://raw.githubusercontent.com/cyberbotics/webots/R2025a/projects/appearances/protos/textures/asphalt/asphalt_roughness.jpg"
                      ]
                      filtering 5
                    }
                    metalness 0
                    IBLStrength 0.5
                    normalMap ImageTexture {
                      url [
                        "https://raw.githubusercontent.com/cyberbotics/webots/R2025a/projects/appearances/protos/textures/asphalt/asphalt_normal.jpg"
                      ]
                      filtering 5
                    }
                    normalMapFactor 1.5
                    occlusionMap ImageTexture {
                      url [
                        "https://raw.githubusercontent.com/cyberbotics/webots/R2025a/projects/appearances/protos/textures/asphalt/asphalt_occlusion.jpg"
                      ]
                      filtering 5
                    }
                    textureTransform TextureTransform {
                      scale 25 25
                    }
                  }
                  geometry Mesh {
                    url [
                      "https://raw.githubusercontent.com/cyberbotics/webots/R2025a/projects/robots/pal_robotics/tiago_base/protos/meshes/small_wheel_shape.obj"
                    ]
                  }
                }
              ]
              name "caster_front_right_2_link"
              boundingObject DEF SMALL_WHEEL_BO Pose {
                children [
                  Cylinder {
                    height 0.015
                    radius 0.025
                  }
                ]
              }
              physics DEF SMALL_WHEEL_PHYSIC Physics {
                density -1
                mass 0.088558
              }
              linearVelocity 0.10413962592298055 0.14095767034345497 -7.477505241955062e-08
              angularVelocity -5.841346187806792 4.02215484857524 -0.9052355110448552
            }
          }
          DEF CASTER_SUPPORT Shape {
            appearance PBRAppearance {
              baseColorMap ImageTexture {
                url [
                  "https://raw.githubusercontent.com/cyberbotics/webots/R2025a/projects/appearances/protos/textures/brushed_aluminium/brushed_aluminium_base_color.jpg"
                ]
              }
              roughnessMap ImageTexture {
                url [
                  "https://raw.githubusercontent.com/cyberbotics/webots/R2025a/projects/appearances/protos/textures/brushed_aluminium/brushed_aluminium_roughness.jpg"
                ]
              }
              normalMap ImageTexture {
                url [
                  "https://raw.githubusercontent.com/cyberbotics/webots/R2025a/projects/appearances/protos/textures/brushed_aluminium/brushed_aluminium_normal.jpg"
                ]
              }
              textureTransform TextureTransform {
                rotation -1.57
                scale 2 2
              }
            }
            geometry Mesh {
              url [
                "https://raw.githubusercontent.com/cyberbotics/webots/R2025a/projects/robots/pal_robotics/tiago_base/protos/meshes/caster_support.obj"
              ]
            }
          }
        ]
        name "caster_front_right_1_link"
        boundingObject DEF CASTER_WHEEL_BO Pose {
          translation -0.003 0 -0.022
          children [
            DEF CASTER_SUPPORT_BO Box {
              size 0.036 0.032 0.04
            }
          ]
        }
        physics DEF CASTER_WHEEL_PHYSIC Physics {
          density -1
          mass 0.051448
        }
        linearVelocity 0.11325613994265844 0.13454647776867654 -1.7973642781777164e-07
        angularVelocity -9.573972231835373e-06 -1.0758362807690714e-08 -0.8558330800379087
      }
    }
    DEF CASTER_WHEEL_FRONT_LEFT_JOINT HingeJoint {
      jointParameters HingeJointParameters {
        position 17.927446929293247
        axis 0 0 1
        anchor 0.1695 0.102 -0.0335
        suspensionSpringConstant 250000
        suspensionAxis 0 0 1
      }
      endPoint DEF CASTER_WHEEL_FRONT_LEFT Solid {
        translation 0.1695 0.102 -0.0335
        rotation 0 0 1 5.361076314934074
        children [
          DEF SMALL_WHEEL_JOINT HingeJoint {
            jointParameters HingeJointParameters {
              position 15943.133687997612
              axis 0 1 0
              anchor -0.016 0 -0.04
            }
            endPoint DEF SMALL_WHEEL Solid {
              translation -0.016 0 -0.04
              rotation 0.1594133702044343 -0.6980629618953847 -0.6980655260288295 3.4577579574284663
              children [
                DEF SMALL_WHEEL_SHAPE Shape {
                  appearance PBRAppearance {
                    baseColorMap ImageTexture {
                      url [
                        "https://raw.githubusercontent.com/cyberbotics/webots/R2025a/projects/appearances/protos/textures/asphalt/asphalt_base_color.jpg"
                      ]
                      filtering 5
                    }
                    roughnessMap ImageTexture {
                      url [
                        "https://raw.githubusercontent.com/cyberbotics/webots/R2025a/projects/appearances/protos/textures/asphalt/asphalt_roughness.jpg"
                      ]
                      filtering 5
                    }
                    metalness 0
                    IBLStrength 0.5
                    normalMap ImageTexture {
                      url [
                        "https://raw.githubusercontent.com/cyberbotics/webots/R2025a/projects/appearances/protos/textures/asphalt/asphalt_normal.jpg"
                      ]
                      filtering 5
                    }
                    normalMapFactor 1.5
                    occlusionMap ImageTexture {
                      url [
                        "https://raw.githubusercontent.com/cyberbotics/webots/R2025a/projects/appearances/protos/textures/asphalt/asphalt_occlusion.jpg"
                      ]
                      filtering 5
                    }
                    textureTransform TextureTransform {
                      scale 25 25
                    }
                  }
                  geometry Mesh {
                    url [
                      "https://raw.githubusercontent.com/cyberbotics/webots/R2025a/projects/robots/pal_robotics/tiago_base/protos/meshes/small_wheel_shape.obj"
                    ]
                  }
                }
              ]
              name "caster_front_left_2_link"
              boundingObject DEF SMALL_WHEEL_BO Pose {
                children [
                  Cylinder {
                    height 0.015
                    radius 0.025
                  }
                ]
              }
              physics DEF SMALL_WHEEL_PHYSIC Physics {
                density -1
                mass 0.088558
              }
              linearVelocity -0.07658802854347577 0.15755253602255112 -1.1745821964731374e-07
              angularVelocity -6.0617569438731005 -3.189029628370247 -0.962915320749148
            }
          }
          DEF CASTER_SUPPORT Shape {
            appearance PBRAppearance {
              baseColorMap ImageTexture {
                url [
                  "https://raw.githubusercontent.com/cyberbotics/webots/R2025a/projects/appearances/protos/textures/brushed_aluminium/brushed_aluminium_base_color.jpg"
                ]
              }
              roughnessMap ImageTexture {
                url [
                  "https://raw.githubusercontent.com/cyberbotics/webots/R2025a/projects/appearances/protos/textures/brushed_aluminium/brushed_aluminium_roughness.jpg"
                ]
              }
              normalMap ImageTexture {
                url [
                  "https://raw.githubusercontent.com/cyberbotics/webots/R2025a/projects/appearances/protos/textures/brushed_aluminium/brushed_aluminium_normal.jpg"
                ]
              }
              textureTransform TextureTransform {
                rotation -1.57
                scale 2 2
              }
            }
            geometry Mesh {
              url [
                "https://raw.githubusercontent.com/cyberbotics/webots/R2025a/projects/robots/pal_robotics/tiago_base/protos/meshes/caster_support.obj"
              ]
            }
          }
        ]
        name "caster_front_left_1_link"
        boundingObject DEF CASTER_WHEEL_BO Pose {
          translation -0.003 0 -0.022
          children [
            DEF CASTER_SUPPORT_BO Box {
              size 0.036 0.032 0.04
            }
          ]
        }
        physics DEF CASTER_WHEEL_PHYSIC Physics {
          density -1
          mass 0.051448
        }
        linearVelocity -0.0660097818260512 0.16298640710108894 -8.14680558885464e-08
        angularVelocity 5.40863490854474e-06 -2.7702828251263615e-06 -0.9124714560876904
      }
    }
    DEF CASTER_WHEEL_BACK_RIGHT_JOINT HingeJoint {
      jointParameters HingeJointParameters {
        position -22.926128767854845
        axis 0 0 1
        anchor -0.1735 -0.102 -0.0335
        suspensionSpringConstant 250000
        suspensionAxis 0 0 1
      }
      endPoint DEF CASTER_WHEEL_BACK_RIGHT Solid {
        translation -0.1735 -0.102 -0.0335
        rotation 0 0 1 2.206612460863501
        children [
          DEF SMALL_WHEEL_JOINT HingeJoint {
            jointParameters HingeJointParameters {
              position 14756.131946995754
              axis 0 1 0
              anchor -0.016 0 -0.04
            }
            endPoint DEF SMALL_WHEEL_JOINT Solid {
              translation -0.016 0 -0.04
              rotation 0.02519447948122263 0.70688102511321 0.7068836216369476 3.191970769977708
              children [
                DEF SMALL_WHEEL_SHAPE Shape {
                  appearance PBRAppearance {
                    baseColorMap ImageTexture {
                      url [
                        "https://raw.githubusercontent.com/cyberbotics/webots/R2025a/projects/appearances/protos/textures/asphalt/asphalt_base_color.jpg"
                      ]
                      filtering 5
                    }
                    roughnessMap ImageTexture {
                      url [
                        "https://raw.githubusercontent.com/cyberbotics/webots/R2025a/projects/appearances/protos/textures/asphalt/asphalt_roughness.jpg"
                      ]
                      filtering 5
                    }
                    metalness 0
                    IBLStrength 0.5
                    normalMap ImageTexture {
                      url [
                        "https://raw.githubusercontent.com/cyberbotics/webots/R2025a/projects/appearances/protos/textures/asphalt/asphalt_normal.jpg"
                      ]
                      filtering 5
                    }
                    normalMapFactor 1.5
                    occlusionMap ImageTexture {
                      url [
                        "https://raw.githubusercontent.com/cyberbotics/webots/R2025a/projects/appearances/protos/textures/asphalt/asphalt_occlusion.jpg"
                      ]
                      filtering 5
                    }
                    textureTransform TextureTransform {
                      scale 25 25
                    }
                  }
                  geometry Mesh {
                    url [
                      "https://raw.githubusercontent.com/cyberbotics/webots/R2025a/projects/robots/pal_robotics/tiago_base/protos/meshes/small_wheel_shape.obj"
                    ]
                  }
                }
              ]
              name "caster_back_right_2_link"
              boundingObject DEF SMALL_WHEEL_BO Pose {
                children [
                  Cylinder {
                    height 0.015
                    radius 0.025
                  }
                ]
              }
              physics DEF SMALL_WHEEL_PHYSIC Physics {
                density -1
                mass 0.088558
              }
              linearVelocity 0.07607068283003986 -0.16125078137174226 4.492925749689738e-07
              angularVelocity 6.20792554368267 3.1658168193671354 -0.9623784833080604
            }
          }
          DEF CASTER_SUPPORT Shape {
            appearance PBRAppearance {
              baseColorMap ImageTexture {
                url [
                  "https://raw.githubusercontent.com/cyberbotics/webots/R2025a/projects/appearances/protos/textures/brushed_aluminium/brushed_aluminium_base_color.jpg"
                ]
              }
              roughnessMap ImageTexture {
                url [
                  "https://raw.githubusercontent.com/cyberbotics/webots/R2025a/projects/appearances/protos/textures/brushed_aluminium/brushed_aluminium_roughness.jpg"
                ]
              }
              normalMap ImageTexture {
                url [
                  "https://raw.githubusercontent.com/cyberbotics/webots/R2025a/projects/appearances/protos/textures/brushed_aluminium/brushed_aluminium_normal.jpg"
                ]
              }
              textureTransform TextureTransform {
                rotation -1.57
                scale 2 2
              }
            }
            geometry Mesh {
              url [
                "https://raw.githubusercontent.com/cyberbotics/webots/R2025a/projects/robots/pal_robotics/tiago_base/protos/meshes/caster_support.obj"
              ]
            }
          }
        ]
        name "caster_back_right_1_link"
        boundingObject DEF CASTER_WHEEL_BO Pose {
          translation -0.003 0 -0.022
          children [
            DEF CASTER_SUPPORT_BO Box {
              size 0.036 0.032 0.04
            }
          ]
        }
        physics DEF CASTER_WHEEL_PHYSIC Physics {
          density -1
          mass 0.051448
        }
        linearVelocity 0.06540778817209343 -0.16654920224764005 4.003421983426166e-07
        angularVelocity 5.873157988871226e-06 -2.979990055963442e-06 -0.9139867024338771
      }
    }
    DEF CASTER_WHEEL_BACK_LEFT_JOINT HingeJoint {
      jointParameters HingeJointParameters {
        position -17.708144979899423
        axis 0 0 1
        anchor -0.1735 0.102 -0.0335
        suspensionSpringConstant 250000
        suspensionAxis 0 0 1
      }
      endPoint DEF CASTER_WHEEL_BACK_LEFT Solid {
        translation -0.1735 0.102 -0.0335
        rotation 0 0 -1 5.14177436554025
        children [
          DEF SMALL_WHEEL_JOINT HingeJoint {
            jointParameters HingeJointParameters {
              position 16032.439891254373
              axis 0 1 0
              anchor -0.016 0 -0.04
            }
            endPoint DEF SMALL_WHEEL Solid {
              translation -0.016 0 -0.04
              rotation -0.32049491183384915 -0.6698058358898115 -0.6698082962285283 2.521291148017253
              children [
                DEF SMALL_WHEEL_SHAPE Shape {
                  appearance PBRAppearance {
                    baseColorMap ImageTexture {
                      url [
                        "https://raw.githubusercontent.com/cyberbotics/webots/R2025a/projects/appearances/protos/textures/asphalt/asphalt_base_color.jpg"
                      ]
                      filtering 5
                    }
                    roughnessMap ImageTexture {
                      url [
                        "https://raw.githubusercontent.com/cyberbotics/webots/R2025a/projects/appearances/protos/textures/asphalt/asphalt_roughness.jpg"
                      ]
                      filtering 5
                    }
                    metalness 0
                    IBLStrength 0.5
                    normalMap ImageTexture {
                      url [
                        "https://raw.githubusercontent.com/cyberbotics/webots/R2025a/projects/appearances/protos/textures/asphalt/asphalt_normal.jpg"
                      ]
                      filtering 5
                    }
                    normalMapFactor 1.5
                    occlusionMap ImageTexture {
                      url [
                        "https://raw.githubusercontent.com/cyberbotics/webots/R2025a/projects/appearances/protos/textures/asphalt/asphalt_occlusion.jpg"
                      ]
                      filtering 5
                    }
                    textureTransform TextureTransform {
                      scale 25 25
                    }
                  }
                  geometry Mesh {
                    url [
                      "https://raw.githubusercontent.com/cyberbotics/webots/R2025a/projects/robots/pal_robotics/tiago_base/protos/meshes/small_wheel_shape.obj"
                    ]
                  }
                }
              ]
              name "caster_back_left_2_link"
              boundingObject DEF SMALL_WHEEL_BO Pose {
                children [
                  Cylinder {
                    height 0.015
                    radius 0.025
                  }
                ]
              }
              physics DEF SMALL_WHEEL_PHYSIC Physics {
                density -1
                mass 0.088558
              }
              linearVelocity -0.10469980892795072 -0.14440730175083136 3.7578675163558226e-07
              angularVelocity 5.980843566184727 -4.046497346889157 -0.9023662218671719
            }
          }
          DEF CASTER_SUPPORT Shape {
            appearance PBRAppearance {
              baseColorMap ImageTexture {
                url [
                  "https://raw.githubusercontent.com/cyberbotics/webots/R2025a/projects/appearances/protos/textures/brushed_aluminium/brushed_aluminium_base_color.jpg"
                ]
              }
              roughnessMap ImageTexture {
                url [
                  "https://raw.githubusercontent.com/cyberbotics/webots/R2025a/projects/appearances/protos/textures/brushed_aluminium/brushed_aluminium_roughness.jpg"
                ]
              }
              normalMap ImageTexture {
                url [
                  "https://raw.githubusercontent.com/cyberbotics/webots/R2025a/projects/appearances/protos/textures/brushed_aluminium/brushed_aluminium_normal.jpg"
                ]
              }
              textureTransform TextureTransform {
                rotation -1.57
                scale 2 2
              }
            }
            geometry Mesh {
              url [
                "https://raw.githubusercontent.com/cyberbotics/webots/R2025a/projects/robots/pal_robotics/tiago_base/protos/meshes/caster_support.obj"
              ]
            }
          }
        ]
        name "caster_back_left_1_link"
        boundingObject DEF CASTER_WHEEL_BO Pose {
          translation -0.003 0 -0.022
          children [
            DEF CASTER_SUPPORT_BO Box {
              size 0.036 0.032 0.04
            }
          ]
        }
        physics DEF CASTER_WHEEL_PHYSIC Physics {
          density -1
          mass 0.051448
        }
        linearVelocity -0.11386541477188998 -0.13806251316844192 4.838238698911196e-07
        angularVelocity -9.410515610922112e-06 2.6365845428590334e-07 -0.8557441105221774
      }
    }
  ]
  name "TIAGo Base"
  model "PAL Robotics - TIAGo Base"
  boundingObject Group {
    children [
      DEF BASE_BO Pose {
        translation 0 0 0.06
        children [
          Shape {
            geometry Cylinder {
              height 0.276
              radius 0.265
            }
          }
        ]
      }
      DEF ANTENNA_LEFT_BO Pose {
        translation -0.201 0.1062 0.28
        children [
          DEF ANTENNA_BO Cylinder {
            height 0.173
            radius 0.007
          }
        ]
      }
      DEF ANTENNA_RIGHT_BO Pose {
        translation -0.201 -0.1062 0.28
        children [
          USE ANTENNA_BO
        ]
      }
    ]
  }
  physics Physics {
    density -1
    mass 28.26649
  }
  controller "tiago_base_controller"
  controllerArgs [
    ""
  ]
  linearVelocity -2.664864691572859e-05 -0.0001397878049650716 1.4683926183075194e-07
  angularVelocity -8.843808643653956e-07 -1.63205433418744e-06 -0.8884952978809996
}
