#VRML_SIM R2025a utf8

EXTERNPROTO "https://raw.githubusercontent.com/cyberbotics/webots/R2025a/projects/objects/backgrounds/protos/TexturedBackground.proto"
EXTERNPROTO "https://raw.githubusercontent.com/cyberbotics/webots/R2025a/projects/objects/backgrounds/protos/TexturedBackgroundLight.proto"
EXTERNPROTO "https://raw.githubusercontent.com/cyberbotics/webots/R2025a/projects/objects/floors/protos/RectangleArena.proto"

WorldInfo {
}
Viewpoint {
  orientation 0.3099692532387087 0.32671627799575104 -0.8928468713834644 1.631471108545188
  position 0.07228927737387456 5.472174172218392 5.457433514205959
}
TexturedBackground {
}
TexturedBackgroundLight {
}
RectangleArena {
  floorSize 5 5
  wallHeight 0.3
}
Robot {
  translation 0.018712283202345543 -0.002575745686418859 0.09400846896406023
  rotation 0.00013844645469020597 0.00019018487359924222 -0.999999972331146 1.2067827019501836
  children [
    DEF BODY_EXTENSION Pose {
    }
    DEF LIDAR Pose {
      translation 0.202 0 -0.004
    }
    Accelerometer {
    }
    InertialUnit {
    }
    Gyro {
    }
    Solid {
      translation 0 0 -0.095
      name "base_footprint"
    }
    DEF BASE_MOBILE_SHAPE Group {
      children [
        DEF BASE Shape {
          appearance PBRAppearance {
            baseColor 0.823529 0.776471 0.776471
            baseColorMap ImageTexture {
              url [
                "https://raw.githubusercontent.com/cyberbotics/webots/R2025a/projects/appearances/protos/textures/matte_car_paint/matte_car_paint_base_color.jpg"
              ]
              filtering 5
            }
            roughnessMap ImageTexture {
              url [
                "https://raw.githubusercontent.com/cyberbotics/webots/R2025a/projects/appearances/protos/textures/glossy_car_paint/glossy_car_paint_roughness.jpg"
              ]
              filtering 5
            }
            metalness 0
            IBLStrength 1.8
            normalMap ImageTexture {
              url [
                "https://raw.githubusercontent.com/cyberbotics/webots/R2025a/projects/appearances/protos/textures/glossy_car_paint/glossy_car_paint_normal.jpg"
              ]
              filtering 5
            }
            normalMapFactor 0.5
            textureTransform TextureTransform {
              scale 4 4
            }
          }
          geometry Mesh {
            url [
              "https://raw.githubusercontent.com/cyberbotics/webots/R2025a/projects/robots/pal_robotics/tiago_base/protos/meshes/base.obj"
            ]
          }
        }
        DEF ANTENNA_LEFT Pose {
          translation -0.201 0.1062 0.195
          children [
            DEF ANTENNA_SHAPE Shape {
              appearance PBRAppearance {
                baseColor 0.133333 0.133333 0.133333
                baseColorMap ImageTexture {
                  url [
                    "https://raw.githubusercontent.com/cyberbotics/webots/R2025a/projects/appearances/protos/textures/matte_car_paint/matte_car_paint_base_color.jpg"
                  ]
                  filtering 5
                }
                roughnessMap ImageTexture {
                  url [
                    "https://raw.githubusercontent.com/cyberbotics/webots/R2025a/projects/appearances/protos/textures/matte_car_paint/matte_car_paint_roughness.jpg"
                  ]
                  filtering 5
                }
                metalness 0
                normalMapFactor 0.5
                textureTransform TextureTransform {
                  scale 10 10
                }
              }
              geometry Mesh {
                url [
                  "https://raw.githubusercontent.com/cyberbotics/webots/R2025a/projects/robots/pal_robotics/tiago_base/protos/meshes/antenna_shape.obj"
                ]
              }
            }
          ]
        }
        DEF ANTENNA_RIGHT Pose {
          translation -0.201 -0.1062 0.195
          children [
            USE ANTENNA_SHAPE
          ]
        }
      ]
    }
    DEF FRONT_SENSOR_1 Pose {
      translation 0.1714 -0.111 0.002
      rotation 0.47980308243485 -0.620398662991083 0.620398662994121 -2.246872814929654
      children [
        Shape {
          appearance PBRAppearance {
            baseColor 0 0 0
          }
          geometry Cylinder {
            height 0.01
            radius 0.01
          }
        }
      ]
      translationStep 0.001
      rotationStep 0.001
    }
    DEF FRONT_SENSOR_2 Pose {
      translation 0.1714 0.111 0.002
      rotation 0.47980308243485 0.620398662991083 0.620398662994121 2.246872814929654
      children [
        Shape {
          appearance PBRAppearance {
            baseColor 0 0 0
          }
          geometry Cylinder {
            height 0.01
            radius 0.01
          }
        }
      ]
      rotationStep 0.001
    }
    DEF BUMPER TouchSensor {
      translation -0.0010810937394454875 3.344817885825996e-05 0.029409894405802425
      rotation -0.03169394728199317 0.9344699276114816 0.35462860586179235 3.182807687351523e-05
      children [
        DEF BUMPER_SHAPE Shape {
          appearance PBRAppearance {
            baseColor 1 0.552941 0.184314
            transparency 0.01
            roughness 0.1
            metalness 0
          }
          geometry Mesh {
            url [
              "https://raw.githubusercontent.com/cyberbotics/webots/R2025a/projects/robots/pal_robotics/tiago_base/protos/meshes/bumper_shape.obj"
            ]
          }
        }
      ]
      name "base_cover_link"
      boundingObject Pose {
        translation 0 0 0.043
        children [
          Cylinder {
            height 0.086
            radius 0.272
          }
        ]
      }
      physics Physics {
        density -1
        mass 0.25821
      }
      linearVelocity 0.0008881910304109574 0.00031890168488299067 3.0019147723707097e-07
      angularVelocity 2.0226442935472976e-07 2.036329211370624e-06 -0.8887609068379311
    }
    DEF DISTANCE_SENSOR_BACK_LEFT DistanceSensor {
      translation -0.183 0.183 0.173
      rotation 0 0 1 2.3562
      children [
        DEF DS_SHAPE Group {
          children [
            DEF DS_SH_1 Pose {
              translation 0 -0.0115 0
              rotation 0 0 1 -1.5707896938995747
              children [
                Shape {
                  appearance PBRAppearance {
                    baseColor 0 0 0
                    baseColorMap ImageTexture {
                      url [
                        "https://raw.githubusercontent.com/cyberbotics/webots/R2025a/projects/appearances/protos/textures/matte_car_paint/matte_car_paint_base_color.jpg"
                      ]
                      filtering 5
                    }
                    roughnessMap ImageTexture {
                      url [
                        "https://raw.githubusercontent.com/cyberbotics/webots/R2025a/projects/appearances/protos/textures/matte_car_paint/matte_car_paint_roughness.jpg"
                      ]
                      filtering 5
                    }
                    metalness 0
                    normalMapFactor 0.5
                    textureTransform TextureTransform {
                      scale 10 10
                    }
                  }
                }
              ]
            }
            DEF DS_SH_2 Pose {
              translation 0 0.0115 0
              rotation 0 0 1 -1.5707896938995747
              children [
                Shape {
                  appearance PBRAppearance {
                    baseColor 0 0 0
                    baseColorMap ImageTexture {
                      url [
                        "https://raw.githubusercontent.com/cyberbotics/webots/R2025a/projects/appearances/protos/textures/matte_car_paint/matte_car_paint_base_color.jpg"
                      ]
                      filtering 5
                    }
                    roughnessMap ImageTexture {
                      url [
                        "https://raw.githubusercontent.com/cyberbotics/webots/R2025a/projects/appearances/protos/textures/matte_car_paint/matte_car_paint_roughness.jpg"
                      ]
                      filtering 5
                    }
                    metalness 0
                    normalMapFactor 0.5
                    textureTransform TextureTransform {
                      scale 10 10
                    }
                  }
                }
              ]
            }
          ]
        }
      ]
      name "base_sonar_03_link"
    }
    DEF DISTANCE_SENSOR_BACK_MIDDLE DistanceSensor {
      translation -0.259 0 0.173
      rotation 0 0 1 3.1416
      children [
        USE DS_SHAPE
      ]
      name "base_sonar_02_link"
    }
    DEF DISTANCE_SENSOR_BACK_RIGHT DistanceSensor {
      translation -0.183 -0.183 0.173
      rotation 0 0 1 3.927
      children [
        USE DS_SHAPE
      ]
      name "base_sonar_01_link"
    }
    DEF RIGHT_WHEEL_JOINT HingeJoint {
      jointParameters HingeJointParameters {
        position 2458.4334449937032
        axis 0 1 0
        anchor 0 -0.2022 0
        suspensionAxis 0 0 1
      }
      device [
        RotationalMotor {
          name "wheel_right_joint"
          acceleration 5.0762
          maxVelocity 10.1523
        }
        PositionSensor {
          name "wheel_right_joint_sensor"
        }
      ]
      endPoint DEF RIGHT_WHEEL Solid {
        translation 0 -0.202 0
        rotation -0.524595498981549 -0.6019953903938373 0.6019976016504309 4.107849328445311
        children [
          DEF BIG_WHEEL Group {
            children [
              Pose {
                translation 0 0 0.042
                children [
                  Shape {
                    appearance PBRAppearance {
                      baseColor 0 0 0
                      roughness 1
                      metalness 0
                    }
                    geometry Cylinder {
                      height 0.005
                      radius 0.016
                    }
                  }
                ]
              }
              DEF TIRE Shape {
                appearance PBRAppearance {
                  baseColorMap ImageTexture {
                    url [
                      "https://raw.githubusercontent.com/cyberbotics/webots/R2025a/projects/appearances/protos/textures/asphalt/asphalt_base_color.jpg"
                    ]
                    filtering 5
                  }
                  roughnessMap ImageTexture {
                    url [
                      "https://raw.githubusercontent.com/cyberbotics/webots/R2025a/projects/appearances/protos/textures/asphalt/asphalt_roughness.jpg"
                    ]
                    filtering 5
                  }
                  metalness 0
                  IBLStrength 0.5
                  normalMap ImageTexture {
                    url [
                      "https://raw.githubusercontent.com/cyberbotics/webots/R2025a/projects/appearances/protos/textures/asphalt/asphalt_normal.jpg"
                    ]
                    filtering 5
                  }
                  normalMapFactor 1.5
                  occlusionMap ImageTexture {
                    url [
                      "https://raw.githubusercontent.com/cyberbotics/webots/R2025a/projects/appearances/protos/textures/asphalt/asphalt_occlusion.jpg"
                    ]
                    filtering 5
                  }
                  textureTransform TextureTransform {
                    scale 25 25
                  }
                }
                geometry Mesh {
                  url [
                    "https://raw.githubusercontent.com/cyberbotics/webots/R2025a/projects/robots/pal_robotics/tiago_base/protos/meshes/tire.obj"
                  ]
                }
              }
              DEF RIM Shape {
                appearance PBRAppearance {
                  baseColorMap ImageTexture {
                    url [
                      "https://raw.githubusercontent.com/cyberbotics/webots/R2025a/projects/robots/pal_robotics/tiago_base/protos/textures/metal_stainless_clean_base_color.jpg"
                    ]
                  }
                  roughnessMap ImageTexture {
                    url [
                      "https://raw.githubusercontent.com/cyberbotics/webots/R2025a/projects/robots/pal_robotics/tiago_base/protos/textures/metal_stainless_clean_roughness.jpg"
                    ]
                  }
                  metalness 0.9
                  textureTransform TextureTransform {
                    scale 10 10
                  }
                }
                geometry Mesh {
                  url [
                    "https://raw.githubusercontent.com/cyberbotics/webots/R2025a/projects/robots/pal_robotics/tiago_base/protos/meshes/rim.obj"
                  ]
                }
              }
            ]
          }
        ]
        name "wheel_right_link"
        boundingObject Pose {
          children [
            Cylinder {
              height 0.04
              radius 0.0985
            }
          ]
        }
        physics Physics {
          density -1
          mass 1.82362
        }
        linearVelocity -0.06649161016951277 0.1671201398537957 6.433352188778239e-07
        angularVelocity -1.8578056004331605 -0.7410659398992662 -0.8970325730172437
      }
    }
    DEF LEFT_WHEEL_JOINT HingeJoint {
      jointParameters HingeJointParameters {
        position 3332.3413513306878
        axis 0 1 0
        anchor 0 0.2022 0
        suspensionAxis 0 0 1
      }
      device [
        RotationalMotor {
          name "wheel_left_joint"
          acceleration 5.0762
          maxVelocity 10.1523
        }
        PositionSensor {
          name "wheel_left_joint_sensor"
        }
      ]
      endPoint DEF LEFT_WHEEL Solid {
        translation 0 0.202 0
        rotation 0.31897147514571195 0.6701693437335318 -0.6701718054074911 2.5240554220959144
        children [
          Pose {
            rotation -1 0 0 3.141593
            children [
              DEF BIG_WHEEL Group {
                children [
                  Pose {
                    translation 0 0 0.042
                    children [
                      Shape {
                        appearance PBRAppearance {
                          baseColor 0 0 0
                          roughness 1
                          metalness 0
                        }
                        geometry Cylinder {
                          height 0.005
                          radius 0.016
                        }
                      }
                    ]
                  }
                  DEF TIRE Shape {
                    appearance PBRAppearance {
                      baseColorMap ImageTexture {
                        url [
                          "https://raw.githubusercontent.com/cyberbotics/webots/R2025a/projects/appearances/protos/textures/asphalt/asphalt_base_color.jpg"
                        ]
                        filtering 5
                      }
                      roughnessMap ImageTexture {
                        url [
                          "https://raw.githubusercontent.com/cyberbotics/webots/R2025a/projects/appearances/protos/textures/asphalt/asphalt_roughness.jpg"
                        ]
                        filtering 5
                      }
                      metalness 0
                      IBLStrength 0.5
                      normalMap ImageTexture {
                        url [
                          "https://raw.githubusercontent.com/cyberbotics/webots/R2025a/projects/appearances/protos/textures/asphalt/asphalt_normal.jpg"
                        ]
                        filtering 5
                      }
                      normalMapFactor 1.5
                      occlusionMap ImageTexture {
                        url [
                          "https://raw.githubusercontent.com/cyberbotics/webots/R2025a/projects/appearances/protos/textures/asphalt/asphalt_occlusion.jpg"
                        ]
                        filtering 5
                      }
                      textureTransform TextureTransform {
                        scale 25 25
                      }
                    }
                    geometry Mesh {
                      url [
                        "https://raw.githubusercontent.com/cyberbotics/webots/R2025a/projects/robots/pal_robotics/tiago_base/protos/meshes/tire.obj"
                      ]
                    }
                  }
                  DEF RIM Shape {
                    appearance PBRAppearance {
                      baseColorMap ImageTexture {
                        url [
                          "https://raw.githubusercontent.com/cyberbotics/webots/R2025a/projects/robots/pal_robotics/tiago_base/protos/textures/metal_stainless_clean_base_color.jpg"
                        ]
                      }
                      roughnessMap ImageTexture {
                        url [
                          "https://raw.githubusercontent.com/cyberbotics/webots/R2025a/projects/robots/pal_robotics/tiago_base/protos/textures/metal_stainless_clean_roughness.jpg"
                        ]
                      }
                      metalness 0.9
                      textureTransform TextureTransform {
                        scale 10 10
                      }
                    }
                    geometry Mesh {
                      url [
                        "https://raw.githubusercontent.com/cyberbotics/webots/R2025a/projects/robots/pal_robotics/tiago_base/protos/meshes/rim.obj"
                      ]
                    }
                  }
                ]
              }
            ]
          }
        ]
        name "wheel_left_link"
        boundingObject Pose {
          children [
            Cylinder {
              height 0.04
              radius 0.0985
            }
          ]
        }
        physics Physics {
          density -1
          mass 1.82362
        }
        linearVelocity 0.06649465524154044 -0.16712434449295635 -5.8200032146863643e-08
        angularVelocity 1.857806617369416 0.7410703418157807 -0.8970048775929524
      }
    }
    DEF CASTER_WHEEL_FRONT_RIGHT_JOINT HingeJoint {
      jointParameters HingeJointParameters {
        position 23.098136170487976
        axis 0 0 1
        anchor 0.1695 -0.102 -0.0335
        suspensionSpringConstant 250000
        suspensionAxis 0 0 1
      }
      endPoint DEF CASTER_WHEEL_FRONT_RIGHT Solid {
        translation 0.1695 -0.102 -0.0335
        rotation 0 0 -1 2.03460505823037
        children [
          DEF SMALL_WHEEL_JOINT HingeJoint {
            jointParameters HingeJointParameters {
              position 7124.714854054786
              axis 0 1 0
              anchor -0.016 0 -0.04
            }
            endPoint DEF SMALL_WHEEL Solid {
              translation -0.016 0 -0.04
              rotation -0.9579786989131404 -0.20282567663859905 -0.20282642166340553 1.6137165525897919
              children [
                DEF SMALL_WHEEL_SHAPE Shape {
                  appearance PBRAppearance {
                    baseColorMap ImageTexture {
                      url [
                        "https://raw.githubusercontent.com/cyberbotics/webots/R2025a/projects/appearances/protos/textures/asphalt/asphalt_base_color.jpg"
                      ]
                      filtering 5
                    }
                    roughnessMap ImageTexture {
                      url [
                        "https://raw.githubusercontent.com/cyberbotics/webots/R2025a/projects/appearances/protos/textures/asphalt/asphalt_roughness.jpg"
                      ]
                      filtering 5
                    }
                    metalness 0
                    IBLStrength 0.5
                    normalMap ImageTexture {
                      url [
                        "https://raw.githubusercontent.com/cyberbotics/webots/R2025a/projects/appearances/protos/textures/asphalt/asphalt_normal.jpg"
                      ]
                      filtering 5
                    }
                    normalMapFactor 1.5
                    occlusionMap ImageTexture {
                      url [
                        "https://raw.githubusercontent.com/cyberbotics/webots/R2025a/projects/appearances/protos/textures/asphalt/asphalt_occlusion.jpg"
                      ]
                      filtering 5
                    }
                    textureTransform TextureTransform {
                      scale 25 25
                    }
                  }
                  geometry Mesh {
                    url [
                      "https://raw.githubusercontent.com/cyberbotics/webots/R2025a/projects/robots/pal_robotics/tiago_base/protos/meshes/small_wheel_shape.obj"
                    ]
                  }
                }
              ]
              name "caster_front_right_2_link"
              boundingObject DEF SMALL_WHEEL_BO Pose {
                children [
                  Cylinder {
                    height 0.015
                    radius 0.025
                  }
                ]
              }
              physics DEF SMALL_WHEEL_PHYSIC Physics {
                density -1
                mass 0.088558
              }
              linearVelocity -0.1750956808579204 0.014620553906384254 3.8017366409467806e-07
              angularVelocity -0.5684468944764498 -7.248269606832488 -0.9302052254524926
            }
          }
          DEF CASTER_SUPPORT Shape {
            appearance PBRAppearance {
              baseColorMap ImageTexture {
                url [
                  "https://raw.githubusercontent.com/cyberbotics/webots/R2025a/projects/appearances/protos/textures/brushed_aluminium/brushed_aluminium_base_color.jpg"
                ]
              }
              roughnessMap ImageTexture {
                url [
                  "https://raw.githubusercontent.com/cyberbotics/webots/R2025a/projects/appearances/protos/textures/brushed_aluminium/brushed_aluminium_roughness.jpg"
                ]
              }
              normalMap ImageTexture {
                url [
                  "https://raw.githubusercontent.com/cyberbotics/webots/R2025a/projects/appearances/protos/textures/brushed_aluminium/brushed_aluminium_normal.jpg"
                ]
              }
              textureTransform TextureTransform {
                rotation -1.57
                scale 2 2
              }
            }
            geometry Mesh {
              url [
                "https://raw.githubusercontent.com/cyberbotics/webots/R2025a/projects/robots/pal_robotics/tiago_base/protos/meshes/caster_support.obj"
              ]
            }
          }
        ]
        name "caster_front_right_1_link"
        boundingObject DEF CASTER_WHEEL_BO Pose {
          translation -0.003 0 -0.022
          children [
            DEF CASTER_SUPPORT_BO Box {
              size 0.036 0.032 0.04
            }
          ]
        }
        physics DEF CASTER_WHEEL_PHYSIC Physics {
          density -1
          mass 0.051448
        }
        linearVelocity -0.17406296462926787 0.025998353702157244 3.577950433084903e-07
        angularVelocity 1.3303474961532589e-06 -9.97106569020753e-07 -0.8762359180252215
      }
    }
    DEF CASTER_WHEEL_FRONT_LEFT_JOINT HingeJoint {
      jointParameters HingeJointParameters {
        position 17.922400024207242
        axis 0 0 1
        anchor 0.1695 0.102 -0.0335
        suspensionSpringConstant 250000
        suspensionAxis 0 0 1
      }
      endPoint DEF CASTER_WHEEL_FRONT_LEFT Solid {
        translation 0.1695 0.102 -0.0335
        rotation 0 0 1 5.356029409848069
        children [
          DEF SMALL_WHEEL_JOINT HingeJoint {
            jointParameters HingeJointParameters {
              position 8535.907550130372
              axis 0 1 0
              anchor -0.016 0 -0.04
            }
            endPoint DEF SMALL_WHEEL Solid {
              translation -0.016 0 -0.04
              rotation 0.07087956087544336 0.7053270280860635 0.7053296189026698 3.283114575147053
              children [
                DEF SMALL_WHEEL_SHAPE Shape {
                  appearance PBRAppearance {
                    baseColorMap ImageTexture {
                      url [
                        "https://raw.githubusercontent.com/cyberbotics/webots/R2025a/projects/appearances/protos/textures/asphalt/asphalt_base_color.jpg"
                      ]
                      filtering 5
                    }
                    roughnessMap ImageTexture {
                      url [
                        "https://raw.githubusercontent.com/cyberbotics/webots/R2025a/projects/appearances/protos/textures/asphalt/asphalt_roughness.jpg"
                      ]
                      filtering 5
                    }
                    metalness 0
                    IBLStrength 0.5
                    normalMap ImageTexture {
                      url [
                        "https://raw.githubusercontent.com/cyberbotics/webots/R2025a/projects/appearances/protos/textures/asphalt/asphalt_normal.jpg"
                      ]
                      filtering 5
                    }
                    normalMapFactor 1.5
                    occlusionMap ImageTexture {
                      url [
                        "https://raw.githubusercontent.com/cyberbotics/webots/R2025a/projects/appearances/protos/textures/asphalt/asphalt_occlusion.jpg"
                      ]
                      filtering 5
                    }
                    textureTransform TextureTransform {
                      scale 25 25
                    }
                  }
                  geometry Mesh {
                    url [
                      "https://raw.githubusercontent.com/cyberbotics/webots/R2025a/projects/robots/pal_robotics/tiago_base/protos/meshes/small_wheel_shape.obj"
                    ]
                  }
                }
              ]
              name "caster_front_left_2_link"
              boundingObject DEF SMALL_WHEEL_BO Pose {
                children [
                  Cylinder {
                    height 0.015
                    radius 0.025
                  }
                ]
              }
              physics DEF SMALL_WHEEL_PHYSIC Physics {
                density -1
                mass 0.088558
              }
              linearVelocity -0.09506751564239935 -0.14734042111799306 1.0823808703269443e-07
              angularVelocity 6.103151275640248 -3.6733190179644786 -0.9000175778360912
            }
          }
          DEF CASTER_SUPPORT Shape {
            appearance PBRAppearance {
              baseColorMap ImageTexture {
                url [
                  "https://raw.githubusercontent.com/cyberbotics/webots/R2025a/projects/appearances/protos/textures/brushed_aluminium/brushed_aluminium_base_color.jpg"
                ]
              }
              roughnessMap ImageTexture {
                url [
                  "https://raw.githubusercontent.com/cyberbotics/webots/R2025a/projects/appearances/protos/textures/brushed_aluminium/brushed_aluminium_roughness.jpg"
                ]
              }
              normalMap ImageTexture {
                url [
                  "https://raw.githubusercontent.com/cyberbotics/webots/R2025a/projects/appearances/protos/textures/brushed_aluminium/brushed_aluminium_normal.jpg"
                ]
              }
              textureTransform TextureTransform {
                rotation -1.57
                scale 2 2
              }
            }
            geometry Mesh {
              url [
                "https://raw.githubusercontent.com/cyberbotics/webots/R2025a/projects/robots/pal_robotics/tiago_base/protos/meshes/caster_support.obj"
              ]
            }
          }
        ]
        name "caster_front_left_1_link"
        boundingObject DEF CASTER_WHEEL_BO Pose {
          translation -0.003 0 -0.022
          children [
            DEF CASTER_SUPPORT_BO Box {
              size 0.036 0.032 0.04
            }
          ]
        }
        physics DEF CASTER_WHEEL_PHYSIC Physics {
          density -1
          mass 0.051448
        }
        linearVelocity -0.10450776344094254 -0.14152850361093214 1.9280526996139386e-08
        angularVelocity 3.762679772525785e-06 -7.290566084653223e-06 -0.8509462410587748
      }
    }
    DEF CASTER_WHEEL_BACK_RIGHT_JOINT HingeJoint {
      jointParameters HingeJointParameters {
        position -22.930110036648717
        axis 0 0 1
        anchor -0.1735 -0.102 -0.0335
        suspensionSpringConstant 250000
        suspensionAxis 0 0 1
      }
      endPoint DEF CASTER_WHEEL_BACK_RIGHT Solid {
        translation -0.1735 -0.102 -0.0335
        rotation 0 0 1 2.202631192069629
        children [
          DEF SMALL_WHEEL_JOINT HingeJoint {
            jointParameters HingeJointParameters {
              position 7220.71413755588
              axis 0 1 0
              anchor -0.016 0 -0.04
            }
            endPoint DEF SMALL_WHEEL_JOINT Solid {
              translation -0.016 0 -0.04
              rotation 0.6680787044651395 -0.5261505539736824 -0.5261524866361157 4.319548322573488
              children [
                DEF SMALL_WHEEL_SHAPE Shape {
                  appearance PBRAppearance {
                    baseColorMap ImageTexture {
                      url [
                        "https://raw.githubusercontent.com/cyberbotics/webots/R2025a/projects/appearances/protos/textures/asphalt/asphalt_base_color.jpg"
                      ]
                      filtering 5
                    }
                    roughnessMap ImageTexture {
                      url [
                        "https://raw.githubusercontent.com/cyberbotics/webots/R2025a/projects/appearances/protos/textures/asphalt/asphalt_roughness.jpg"
                      ]
                      filtering 5
                    }
                    metalness 0
                    IBLStrength 0.5
                    normalMap ImageTexture {
                      url [
                        "https://raw.githubusercontent.com/cyberbotics/webots/R2025a/projects/appearances/protos/textures/asphalt/asphalt_normal.jpg"
                      ]
                      filtering 5
                    }
                    normalMapFactor 1.5
                    occlusionMap ImageTexture {
                      url [
                        "https://raw.githubusercontent.com/cyberbotics/webots/R2025a/projects/appearances/protos/textures/asphalt/asphalt_occlusion.jpg"
                      ]
                      filtering 5
                    }
                    textureTransform TextureTransform {
                      scale 25 25
                    }
                  }
                  geometry Mesh {
                    url [
                      "https://raw.githubusercontent.com/cyberbotics/webots/R2025a/projects/robots/pal_robotics/tiago_base/protos/meshes/small_wheel_shape.obj"
                    ]
                  }
                }
              ]
              name "caster_back_right_2_link"
              boundingObject DEF SMALL_WHEEL_BO Pose {
                children [
                  Cylinder {
                    height 0.015
                    radius 0.025
                  }
                ]
              }
              physics DEF SMALL_WHEEL_PHYSIC Physics {
                density -1
                mass 0.088558
              }
              linearVelocity 0.09847524390332062 0.14881276751656836 4.788457851883855e-07
              angularVelocity -6.161436055993011 3.8069731139557113 -0.8993443797599381
            }
          }
          DEF CASTER_SUPPORT Shape {
            appearance PBRAppearance {
              baseColorMap ImageTexture {
                url [
                  "https://raw.githubusercontent.com/cyberbotics/webots/R2025a/projects/appearances/protos/textures/brushed_aluminium/brushed_aluminium_base_color.jpg"
                ]
              }
              roughnessMap ImageTexture {
                url [
                  "https://raw.githubusercontent.com/cyberbotics/webots/R2025a/projects/appearances/protos/textures/brushed_aluminium/brushed_aluminium_roughness.jpg"
                ]
              }
              normalMap ImageTexture {
                url [
                  "https://raw.githubusercontent.com/cyberbotics/webots/R2025a/projects/appearances/protos/textures/brushed_aluminium/brushed_aluminium_normal.jpg"
                ]
              }
              textureTransform TextureTransform {
                rotation -1.57
                scale 2 2
              }
            }
            geometry Mesh {
              url [
                "https://raw.githubusercontent.com/cyberbotics/webots/R2025a/projects/robots/pal_robotics/tiago_base/protos/meshes/caster_support.obj"
              ]
            }
          }
        ]
        name "caster_back_right_1_link"
        boundingObject DEF CASTER_WHEEL_BO Pose {
          translation -0.003 0 -0.022
          children [
            DEF CASTER_SUPPORT_BO Box {
              size 0.036 0.032 0.04
            }
          ]
        }
        physics DEF CASTER_WHEEL_PHYSIC Physics {
          density -1
          mass 0.051448
        }
        linearVelocity 0.10785611636196699 0.14287704763108988 5.757917319199023e-07
        angularVelocity 3.431353836278144e-06 -7.197292803774955e-06 -0.8525160342228396
      }
    }
    DEF CASTER_WHEEL_BACK_LEFT_JOINT HingeJoint {
      jointParameters HingeJointParameters {
        position -17.73400792231565
        axis 0 0 1
        anchor -0.1735 0.102 -0.0335
        suspensionSpringConstant 250000
        suspensionAxis 0 0 1
      }
      endPoint DEF CASTER_WHEEL_BACK_LEFT Solid {
        translation -0.1735 0.102 -0.0335
        rotation 0 0 -1 5.167637307956479
        children [
          DEF SMALL_WHEEL_JOINT HingeJoint {
            jointParameters HingeJointParameters {
              position 8495.262793435248
              axis 0 1 0
              anchor -0.016 0 -0.04
            }
            endPoint DEF SMALL_WHEEL Solid {
              translation -0.016 0 -0.04
              rotation -0.9619782680614488 0.1931288918888587 0.19312960129218185 1.6095537121618415
              children [
                DEF SMALL_WHEEL_SHAPE Shape {
                  appearance PBRAppearance {
                    baseColorMap ImageTexture {
                      url [
                        "https://raw.githubusercontent.com/cyberbotics/webots/R2025a/projects/appearances/protos/textures/asphalt/asphalt_base_color.jpg"
                      ]
                      filtering 5
                    }
                    roughnessMap ImageTexture {
                      url [
                        "https://raw.githubusercontent.com/cyberbotics/webots/R2025a/projects/appearances/protos/textures/asphalt/asphalt_roughness.jpg"
                      ]
                      filtering 5
                    }
                    metalness 0
                    IBLStrength 0.5
                    normalMap ImageTexture {
                      url [
                        "https://raw.githubusercontent.com/cyberbotics/webots/R2025a/projects/appearances/protos/textures/asphalt/asphalt_normal.jpg"
                      ]
                      filtering 5
                    }
                    normalMapFactor 1.5
                    occlusionMap ImageTexture {
                      url [
                        "https://raw.githubusercontent.com/cyberbotics/webots/R2025a/projects/appearances/protos/textures/asphalt/asphalt_occlusion.jpg"
                      ]
                      filtering 5
                    }
                    textureTransform TextureTransform {
                      scale 25 25
                    }
                  }
                  geometry Mesh {
                    url [
                      "https://raw.githubusercontent.com/cyberbotics/webots/R2025a/projects/robots/pal_robotics/tiago_base/protos/meshes/small_wheel_shape.obj"
                    ]
                  }
                }
              ]
              name "caster_back_left_2_link"
              boundingObject DEF SMALL_WHEEL_BO Pose {
                children [
                  Cylinder {
                    height 0.015
                    radius 0.025
                  }
                ]
              }
              physics DEF SMALL_WHEEL_PHYSIC Physics {
                density -1
                mass 0.088558
              }
              linearVelocity 0.1783231284540657 -0.013179192239260796 2.6709946909226596e-07
              angularVelocity 0.5130501802515527 7.379846908755217 -0.9340827072448658
            }
          }
          DEF CASTER_SUPPORT Shape {
            appearance PBRAppearance {
              baseColorMap ImageTexture {
                url [
                  "https://raw.githubusercontent.com/cyberbotics/webots/R2025a/projects/appearances/protos/textures/brushed_aluminium/brushed_aluminium_base_color.jpg"
                ]
              }
              roughnessMap ImageTexture {
                url [
                  "https://raw.githubusercontent.com/cyberbotics/webots/R2025a/projects/appearances/protos/textures/brushed_aluminium/brushed_aluminium_roughness.jpg"
                ]
              }
              normalMap ImageTexture {
                url [
                  "https://raw.githubusercontent.com/cyberbotics/webots/R2025a/projects/appearances/protos/textures/brushed_aluminium/brushed_aluminium_normal.jpg"
                ]
              }
              textureTransform TextureTransform {
                rotation -1.57
                scale 2 2
              }
            }
            geometry Mesh {
              url [
                "https://raw.githubusercontent.com/cyberbotics/webots/R2025a/projects/robots/pal_robotics/tiago_base/protos/meshes/caster_support.obj"
              ]
            }
          }
        ]
        name "caster_back_left_1_link"
        boundingObject DEF CASTER_WHEEL_BO Pose {
          translation -0.003 0 -0.022
          children [
            DEF CASTER_SUPPORT_BO Box {
              size 0.036 0.032 0.04
            }
          ]
        }
        physics DEF CASTER_WHEEL_PHYSIC Physics {
          density -1
          mass 0.051448
        }
        linearVelocity 0.17737699433702003 -0.02465456342813699 2.4653554230464605e-07
        angularVelocity 1.2707501511949886e-06 5.994153484566142e-07 -0.8828169443378275
      }
    }
  ]
  name "TIAGo Base"
  model "PAL Robotics - TIAGo Base"
  boundingObject Group {
    children [
      DEF BASE_BO Pose {
        translation 0 0 0.06
        children [
          Shape {
            geometry Cylinder {
              height 0.276
              radius 0.265
            }
          }
        ]
      }
      DEF ANTENNA_LEFT_BO Pose {
        translation -0.201 0.1062 0.28
        children [
          DEF ANTENNA_BO Cylinder {
            height 0.173
            radius 0.007
          }
        ]
      }
      DEF ANTENNA_RIGHT_BO Pose {
        translation -0.201 -0.1062 0.28
        children [
          USE ANTENNA_BO
        ]
      }
    ]
  }
  physics Physics {
    density -1
    mass 28.26649
  }
  controller "tiago_base_controller"
  controllerArgs [
    ""
  ]
  linearVelocity 0.00013319530850466557 5.085268782556637e-05 2.99401754843056e-07
  angularVelocity 2.022657641133985e-07 2.0363286295893917e-06 -0.8887609068177879
}
